Workbook
Name \0: #REF!
Name \1: #REF!
Name \a: #REF!
Name \b: #REF!
Name \c: #REF!
Name \e: #REF!
Name \p: #REF!
Name \x: #REF!
Name \z: #REF!
Name _: #REF!
Name _________________________esc15: "#ref!"
Name _________________________esc4: "#ref!"
Name _________________________esc6: "#ref!"
Name ________________________esc15: "#ref!"
Name ________________________esc4: "#ref!"
Name ________________________esc6: "#ref!"
Name _______________________esc15: "#ref!"
Name _______________________esc4: "#ref!"
Name _______________________esc6: "#ref!"
Name ______________________esc15: "#ref!"
Name ______________________esc4: "#ref!"
Name ______________________esc6: "#ref!"
Name _____________________pv3: #REF!
Name ____________________Ele200502: #REF!
Name ____________________esc15: "#ref!"
Name ____________________esc4: "#ref!"
Name ____________________esc6: "#ref!"
Name ____________________pv3: #REF!
Name ____________________Ser200705: #REF!
Name ____________________Ser200712: #REF!
Name ____________________Ser201104: #REF!
Name ____________________TR2: #REF!
Name ____________________TR5: #REF!
Name ___________________Ele200502: #REF!
Name ___________________Ele200609: #REF!
Name ___________________esc15: "#ref!"
Name ___________________esc4: "#ref!"
Name ___________________esc6: "#ref!"
Name ___________________pv2: #REF!
Name ___________________pv3: #REF!
Name ___________________Ser200506: #REF!
Name ___________________Ser200705: #REF!
Name ___________________Ser200712: #REF!
Name ___________________Ser201104: #REF!
Name ___________________TR2: #REF!
Name ___________________TR5: #REF!
Name __________________Ele200502: #REF!
Name __________________Ele200609: #REF!
Name __________________esc15: "#ref!"
Name __________________esc4: "#ref!"
Name __________________esc6: "#ref!"
Name __________________pv2: #REF!
Name __________________pv3: #REF!
Name __________________Ser200506: #REF!
Name __________________Ser200705: #REF!
Name __________________Ser200712: #REF!
Name __________________Ser201104: #REF!
Name __________________TR2: #REF!
Name __________________TR5: #REF!
Name _________________Ele200502: #REF!

Sheet TabelaVarreçãoMec
A1: SERVIÇO | B1: DATA | C1: LOCAL | D1: TIPO DE EQUIPAMENTO | E1: UNIDADE | F1: QUANTIDADE | G1: OBSERVAÇÃO
A2: VARREÇÃO MECANIZADA | B2: 46290 | C2: SETOR 3 | D2: VARREDEIRA MECANIZADA | E2: KM | F2: 52.869 | G2: SEG, QUA, SEX
A3: VARREÇÃO MECANIZADA | B3: 46290 | C3: SETOR 5 | D3: VARREDEIRA MECANIZADA | E3: KM | F3: 52.811 | G3: SEG, QUA, SEX
A4: VARREÇÃO MECANIZADA | B4: 46290 | C4: SETOR 7 | D4: VARREDEIRA MECANIZADA | E4: KM | F4: 53.756 | G4: SEG, QUA, SEX
A5: VARREÇÃO MECANIZADA | B5: 46291 | C5: SETOR 10 | D5: VARREDEIRA MECANIZADA | E5: KM | F5: 49.761 | G5: TER, QUI , SÁB
A6: VARREÇÃO MECANIZADA | B6: 46291 | C6: SETOR 8 | D6: VARREDEIRA MECANIZADA | E6: KM | F6: 52.217 | G6: TER, QUI , SÁB
A7: VARREÇÃO MECANIZADA | B7: 46293 | C7: SETOR 3 | D7: VARREDEIRA MECANIZADA | E7: KM | F7: 52.869 | G7: SEG, QUA, SEX
A8: VARREÇÃO MECANIZADA | B8: 46293 | C8: SETOR 5 | D8: VARREDEIRA MECANIZADA | E8: KM | F8: 52.811 | G8: SEG, QUA, SEX
A9: VARREÇÃO MECANIZADA | B9: 46293 | C9: SETOR 7 | D9: VARREDEIRA MECANIZADA | E9: KM | F9: 53.756 | G9: SEG, QUA, SEX
A10: VARREÇÃO MECANIZADA | B10: 46294 | C10: SETOR 10 | D10: VARREDEIRA MECANIZADA | E10: KM | F10: 49.761 | G10: TER, QUI , SÁB
A11: VARREÇÃO MECANIZADA | B11: 46294 | C11: SETOR 8 | D11: VARREDEIRA MECANIZADA | E11: KM | F11: 52.217 | G11: TER, QUI , SÁB
A12: VARREÇÃO MECANIZADA | B12: 46295 | C12: SETOR 3 | D12: VARREDEIRA MECANIZADA | E12: KM | F12: 52.869 | G12: SEG, QUA, SEX
A13: VARREÇÃO MECANIZADA | B13: 46295 | C13: SETOR 5 | D13: VARREDEIRA MECANIZADA | E13: KM | F13: 52.811 | G13: SEG, QUA, SEX
... A38: VARREÇÃO MECANIZADA | B38: 46308 | C38: SETOR 8 | D38: VARREDEIRA MECANIZADA | E38: KM | F38: 52.217 | G38: TER, QUI , SÁB

Sheet Vias p Setor
C2: OBJETO: Contratação de empresa especializada para a prestação de “Serviços de limpeza pública urbana do município de Aparecida de Goiânia, Estado de Goiás, compreendendo os serviços de coleta domiciliar e comercial, varrição mecanizada, varrição manual, e equipe de serviços diversos de remoção de entulhos e materiais inservíveis, capina e raspagem”
C3: CONCORRÊNCIA PÚBLICA TIPO: MENOR PREÇO N° 012/2023
C4: CONTRATO: | D4: =#REF! -> #REF!
C5: DATA: | D5: =#REF! -> #REF!
C6: CONTRATADA: CONSÓRCIO SQ APARECIDA SUSTENTÁVEL - CNPJ.: 56.309.119/0001-03
C7: PERÍODO: | D7: =#REF! -> #REF!
B9: =#REF! -> #REF!
B11: SETORES X AVENIDAS E RUAS X FREQUÊNCIA
B12: RÓTULOS DE LINHA | C12: SOMA DE COMP (D) | D12: SETOR | E12: FREQUÊNCIA
B13: AVENIDA ATLANTICA | C13: 0.062 | D13: 1 | E13: SEG QUA SEX 1
B14: AVENIDA LIBERDADE | C14: 0.104 | D14: 1 | E14: SEG QUA SEX 1
B15: AVENIDA MARACANA | C15: 0.058 | D15: 1 | E15: SEG QUA SEX 1
B16: AVENIDA TROPICAL | C16: 0.079 | D16: 1 | E16: SEG QUA SEX 1
B17: AVENIDA UNIAO | C17: 0.063 | D17: 1 | E17: SEG QUA SEX 1
B18: AVENIDA 13 DE MAIO | C18: 0.236 | D18: 1 | E18: SEG QUA SEX 1
B19: AVENIDA ATLANTICA | C19: 10.162 | D19: 1 | E19: SEG QUA SEX 1
B20: AVENIDA C | C20: 0.072 | D20: 1 | E20: SEG QUA SEX 1
B21: AVENIDA DA PAZ | C21: 3.13 | D21: 1 | E21: SEG QUA SEX 1
B22: AVENIDA DEMOCRATAS | C22: 2.615 | D22: 1 | E22: SEG QUA SEX 1
B23: AVENIDA DOM PEDRO I | C23: 0.189 | D23: 1 | E23: SEG QUA SEX 1
B24: AVENIDA DUQUE DE CAXIAS | C24: 0.983 | D24: 1 | E24: SEG QUA SEX 1
... B51: RUA GENERAL URQUIZA | C51: 0.053 | D51: 1 | E51: SEG QUA SEX 1
B52: SETOR 1 | C52: =SUM(C13:C51) -> 41.062
B53: AVENIDA EPIACAUBA | C53: 0.052 | D53: 2 | E53: SEG QUA SEX 2
B54: AVENIDA RIO VERDE | C54: 0.897 | D54: 2 | E54: SEG QUA SEX 2
B55: AVENIDA CAPIABA | C55: 7.271 | D55: 2 | E55: SEG QUA SEX 2
B56: AVENIDA CARAÍBA | C56: 1.95 | D56: 2 | E56: SEG QUA SEX 2
B57: AVENIDA CURUSSA | C57: 8.901 | D57: 2 | E57: SEG QUA SEX 2
B58: AVENIDA EPICAUBA | C58: 0.222 | D58: 2 | E58: SEG QUA SEX 2
B59: AVENIDA GUIRAUPI | C59: 0.018 | D59: 2 | E59: SEG QUA SEX 2
B60: AVENIDA RIO VERDE | C60: 31.344 | D60: 2 | E60: SEG QUA SEX 2
B61: AVENIDA SÃO PAULO | C61: 0.038 | D61: 2 | E61: SEG QUA SEX 2
B62: RUA VINTE E CINCO C | C62: 0.05 | D62: 2 | E62: SEG QUA SEX 2
B63: SETOR 2 | C63: =SUM(C53:C62) -> 50.743
B64: AVENIDA ANCHIETA | C64: 0.906 | D64: 3 | E64: SEG QUA SEX 3
B65: AVENIDA EPIACAUBA | C65: 0.087 | D65: 3 | E65: SEG QUA SEX 3
B66: AVENIDA GUYRAUPIA | C66: 0.647 | D66: 3 | E66: SEG QUA SEX 3
B67: AVENIDA LIBERDADE | C67: 0.135 | D67: 3 | E67: SEG QUA SEX 3
B68: AVENIDA RIO VERDE | C68: 0.052 | D68: 3 | E68: SEG QUA SEX 3
B69: AVENIDA UNIAO | C69: 1.412 | D69: 3 | E69: SEG QUA SEX 3
...

Sheet CONSOLIDADO
A1: SERVIÇO | B1: DATA | C1: LOCAL | D1: TIPO DE EQUIPAMENTO | E1: UNIDADE | F1: QUANTIDADE | G1: OBSERVAÇÃO
A2: ROÇADA MANUAL | B2: 46167 | C2: Trindade CENTO E TRINTA E SEIS | E2: m² | F2: 1186.9089
A3: ROÇADA MANUAL | B3: 46167 | C3: Trindade CENTO E TRINTA E SEIS | E3: m² | F3: 1887.8866
A4: ROÇADA MANUAL | B4: 46175 | C4: Independencia 1 Com. St. das Mansoes CENTO E TRINTA E SEIS | E4: m² | F4: 952.23532
A5: ROÇADA MANUAL | B5: 46175 | C5: Independencia 1 Com. St. das Mansoes CENTO E TRINTA E SEIS | E5: m² | F5: 1928.5245
A6: ROÇADA MANUAL | B6: 46175 | C6: Independencia 1 Com. St. das Mansoes CENTO E TRINTA E SEIS | E6: m² | F6: 1970.0997
A7: ROÇADA MANUAL | B7: 46175 | C7: Independencia 1 Com. St. das Mansoes CENTO E TRINTA E SEIS | E7: m² | F7: 1980.4117
A8: ROÇADA MANUAL | B8: 46175 | C8: Independencia 1 Com. St. das Mansoes CENTO E TRINTA E SEIS | E8: m² | F8: 2003.5244
A9: ROÇADA MANUAL | B9: 46182 | C9: Cidade Satelite Sao Luiz CENTO E TRINTA E SEIS | E9: m² | F9: 1232.0563
A10: ROÇADA MANUAL | B10: 46182 | C10: Cruzeiro do Sul CENTO E TRINTA E SEIS | E10: m² | F10: 208.78767
A11: ROÇADA MANUAL | B11: 46182 | C11: Cruzeiro do Sul CENTO E TRINTA E SEIS | E11: m² | F11: 621.05349
A12: ROÇADA MANUAL | B12: 46182 | C12: Cruzeiro do Sul CENTO E TRINTA E SEIS | E12: m² | F12: 893.83746
A13: ROÇADA MANUAL | B13: 46182 | C13: Cruzeiro do Sul CENTO E TRINTA E SEIS | E13: m² | F13: 1262.2733
... A22: ROÇADA MANUAL | B22: 46196 | C22: Cidade Vera Cruz CENTO E TRINTA E SEIS | E22: m² | F22: 1305.5097
A23: Entulho/Remoção | B23: 46290 | C23: Cidade Satelite São Luiz Rua Gilberto Freire 152 | D23: CAÇAMBA | E23: EQUIPE
A24: Entulho/Remoção | B24: 46290 | C24: Colina Azul Av. Flamingo 156-184 | D24: CAÇAMBA | E24: EQUIPE
A25: Entulho/Remoção | B25: 46290 | C25: Colina Azul Rua Cardeal 679 | D25: CAÇAMBA | E25: EQUIPE
A26: Entulho/Remoção | B26: 46290 | C26: Conj. Cruzeiro Do Sul Rua Dos Limoeiros 13 | D26: CAÇAMBA | E26: EQUIPE
A27: Entulho/Remoção | B27: 46290 | C27: Jardim Boa Esperança Rua C9 1750 | D27: CAÇAMBA | E27: EQUIPE
A28: Entulho/Remoção | B28: 46290 | C28: Jardim Dom Bosco Rua Domingos Povoa Borges 376 | D28: CAÇAMBA | E28: EQUIPE
A29: Entulho/Remoção | B29: 46290 | C29: Jardim Dom Bosco Rua Valter De Jesus 183 | D29: CAÇAMBA | E29: EQUIPE
A30: Entulho/Remoção | B30: 46290 | C30: Nova Brasilia Av. Graça Aranha Qd.26 Lt.03 | D30: CAÇAMBA | E30: EQUIPE
A31: LIMPEZA DE FEIRAS | B31: 46290 | C31: Avenida Adalberto Ferreira Setor Santo André | D31: CAMINHÃO PIPA | E31: EQUIPE
A32: LIMPEZA DE FEIRAS | B32: 46290 | C32: Avenida Anchieta Setor Pontal Sul | D32: CAMINHÃO PIPA | E32: EQUIPE
A33: LIMPEZA DE FEIRAS | B33: 46290 | C33: Avenida Boa Esperança Jardim Buriti Sereno | D33: CAMINHÃO PIPA | E33: EQUIPE
A34: LIMPEZA DE FEIRAS | B34: 46290 | C34: Avenida Rita Campos Serra Dourada 2 | D34: CAMINHÃO PIPA | E34: EQUIPE
... A40: LIMPEZA DE FEIRAS | B40: 46290 | C40: Rua do Cravo Jardim dos Buritis | D40: CAMINHÃO PIPA | E40: EQUIPE
A41: ROÇADA MANUAL | B41: 46290 | C41: Aeroporto Sul CENTO E TRINTA E SEIS | E41: m² | F41: 1207.2832
A42: ROÇADA MANUAL | B42: 46290 | C42: Bandeirantes CENTO E TRINTA E SEIS | E42: m² | F42: 208.0857
A43: ROÇADA MANUAL | B43: 46290 | C43: Bandeirantes CENTO E TRINTA E SEIS | E43: m² | F43: 300.02622
A44: ROÇADA MANUAL | B44: 46290 | C44: Bandeirantes CENTO E TRINTA E SEIS | E44: m² | F44: 624.51004
A45: ROÇADA MANUAL | B45: 46290 | C45: Bandeirantes CENTO E TRINTA E SEIS | E45: m² | F45: 928.70568
A46: ROÇADA MANUAL | B46: 46290 | C46: Bandeirantes CENTO E TRINTA E SEIS | E46: m² | F46: 928.70568
A47: ROÇADA MANUAL | B47: 46290 | C47: Bandeirantes CENTO E TRINTA E SEIS | E47: m² | F47: 928.7057
A48: ROÇADA MANUAL | B48: 46290 | C48: Bandeirantes CENTO E TRINTA E SEIS | E48: m² | F48: 1207.8454
A49: ROÇADA MANUAL | B49: 46290 | C49: Bandeirantes CENTO E TRINTA E SEIS | E49: m² | F49: 2330.2555
A50: ROÇADA MANUAL | B50: 46290 | C50: Bandeirantes CENTO E TRINTA E SEIS | E50: m² | F50: 2330.4089
A51: ROÇADA MANUAL | B51: 46290 | C51: Cardoso CENTO E TRINTA E SEIS | E51: m² | F51: 415.3809
A52: ROÇADA MANUAL | B52: 46290 | C52: Cardoso CENTO E TRINTA E SEIS | E52: m² | F52: 493.43773
... A114: ROÇADA MANUAL | B114: 46290 | C114: Trindade CENTO E TRINTA E SEIS | E114: m² | F114: 1090.68
...

Sheet MAPA VARRIÇÃO MECANIZADA
D2: OBJETO: | E2: Contratação de empresa especializada para a prestação de “Serviços de limpeza pública urbana do município de Aparecida de Goiânia, Estado de Goiás, compreendendo os serviços de coleta domiciliar e comercial, varrição mecanizada, varrição manual, e equipe de serviços diversos de remoção de entulhos e materiais inservíveis, capina e raspagem”
D3: CONTRATO: | E3: =#REF! -> #REF! | G3: CONCORRÊNCIA PÚBLICA TIPO: MENOR PREÇO N° 012/2023
D4: DATA: | E4: =#REF! -> #REF! | G4: CONTRATADA: CONSORCIO SQ APARECIDA SUSTENTÁVEL - CNPJ.: 56.309.119/0001-03
D5: PERÍODO: | E5: =#REF! -> #REF!
B7: ="ITEM - MAPA DE APONTAMENTO DOS SERVIÇOS DE VARRIÇÃO MECANIZADA DE VIAS - SARJETAS - "&#REF! -> #REF!
G9: =WEEKDAY(G10) -> 6 | H9: =WEEKDAY(H10) -> 7 | I9: =WEEKDAY(I10) -> 1 | J9: =WEEKDAY(J10) -> 2 | K9: =WEEKDAY(K10) -> 3 | L9: =WEEKDAY(L10) -> 4 | M9: =WEEKDAY(M10) -> 5 | N9: =WEEKDAY(N10) -> 6 | ... AK9: =WEEKDAY(AK10) -> 5
B10: LOCAL | C10: FREQUENCIA | D10: COMP SARJETA (KM) | E10: TOTAL KM POR MÊS | F10: NÚMERO DE EXECUÇÕES | G10: 25-set-26 | H10: 26-set-26 | I10: 27-set-26 | J10: 28-set-26 | K10: 29-set-26 | L10: 30-set-26 | M10: 1-out-26 | N10: 2-out-26 | O10: 3-out-26 | P10: 4-out-26 | Q10: 5-out-26 | R10: 6-out-26 | S10: 7-out-26 | T10: 8-out-26 | U10: 9-out-26 | V10: 10-out-26 | W10: 11-out-26 | X10: 12-out-26 | Y10: 13-out-26 | Z10: 14-out-26 | AA10: 15-out-26 | AB10: 16-out-26 | AC10: 17-out-26 | AD10: 18-out-26 | AE10: 19-out-26 | AF10: 20-out-26 | AG10: 21-out-26 | AH10: 22-out-26 | AI10: 23-out-26 | AJ10: 24-out-26 | AK10: 24-set-26
B11: SETOR 1 | C11: SEG, QUA, SEX | D11: =VLOOKUP(B11,'Vias p Setor'!B:F,2,FALSE) -> 41.062 | E11: =F11*D11 -> 0 | F11: =SUM(G11:AJ11) -> 0
B12: SETOR 2 | C12: SEG, QUA, SEX | D12: =VLOOKUP(B12,'Vias p Setor'!B:F,2,FALSE) -> 50.743 | E12: =F12*D12 -> 0 | F12: =SUM(G12:AJ12) -> 0
B13: SETOR 3 | C13: SEG, QUA, SEX | D13: =VLOOKUP(B13,'Vias p Setor'!B:F,2,FALSE) -> 52.869 | E13: =F13*D13 -> 634.428 | F13: =SUM(G13:AJ13) -> 12 | G13: =IF(OR(G$9=2,G$9=4,G$9=6),1,0) -> 1 | H13: =IF(OR(H$9=2,H$9=4,H$9=6),1,0) -> 0 | I13: =IF(OR(I$9=2,I$9=4,I$9=6),1,0) -> 0 | J13: =IF(OR(J$9=2,J$9=4,J$9=6),1,0) -> 1 | K13: =IF(OR(K$9=2,K$9=4,K$9=6),1,0) -> 0 | L13: =IF(OR(L$9=2,L$9=4,L$9=6),1,0) -> 1 | M13: =IF(OR(M$9=2,M$9=4,M$9=6),1,0) -> 0 | N13: =IF(OR(N$9=2,N$9=4,N$9=6),1,0) -> 1 | ... W13: =IF(OR(W$9=2,W$9=4,W$9=6),1,0) -> 0 | Y13: =IF(OR(Y$9=2,Y$9=4,Y$9=6),1,0) -> 0 | Z13: =IF(OR(Z$9=2,Z$9=4,Z$9=6),1,0) -> 1 | AA13: =IF(OR(AA$9=2,AA$9=4,AA$9=6),1,0) -> 0 | AB13: =IF(OR(AB$9=2,AB$9=4,AB$9=6),1,0) -> 1 | AC13: =IF(OR(AC$9=2,AC$9=4,AC$9=6),1,0) -> 0 | AD13: =IF(OR(AD$9=2,AD$9=4,AD$9=6),1,0) -> 0 | AE13: =IF(OR(AE$9=2,AE$9=4,AE$9=6),1,0) -> 1 | AF13: =IF(OR(AF$9=2,AF$9=4,AF$9=6),1,0) -> 0 | ... AI13: =IF(OR(AI$9=2,AI$9=4,AI$9=6),1,0) -> 1
B14: SETOR 4 | C14: SEG, QUA, SEX | D14: =VLOOKUP(B14,'Vias p Setor'!B:F,2,FALSE) -> 51.476 | E14: =F14*D14 -> 0 | F14: =SUM(G14:AJ14) -> 0
B15: SETOR 5 | C15: SEG, QUA, SEX | D15: =VLOOKUP(B15,'Vias p Setor'!B:F,2,FALSE) -> 52.811 | E15: =F15*D15 -> 633.732 | F15: =SUM(G15:AJ15) -> 12 | G15: =IF(OR(G$9=2,G$9=4,G$9=6),1,0) -> 1 | H15: =IF(OR(H$9=2,H$9=4,H$9=6),1,0) -> 0 | I15: =IF(OR(I$9=2,I$9=4,I$9=6),1,0) -> 0 | J15: =IF(OR(J$9=2,J$9=4,J$9=6),1,0) -> 1 | K15: =IF(OR(K$9=2,K$9=4,K$9=6),1,0) -> 0 | L15: =IF(OR(L$9=2,L$9=4,L$9=6),1,0) -> 1 | M15: =IF(OR(M$9=2,M$9=4,M$9=6),1,0) -> 0 | N15: =IF(OR(N$9=2,N$9=4,N$9=6),1,0) -> 1 | ... W15: =IF(OR(W$9=2,W$9=4,W$9=6),1,0) -> 0 | Y15: =IF(OR(Y$9=2,Y$9=4,Y$9=6),1,0) -> 0 | Z15: =IF(OR(Z$9=2,Z$9=4,Z$9=6),1,0) -> 1 | AA15: =IF(OR(AA$9=2,AA$9=4,AA$9=6),1,0) -> 0 | AB15: =IF(OR(AB$9=2,AB$9=4,AB$9=6),1,0) -> 1 | AC15: =IF(OR(AC$9=2,AC$9=4,AC$9=6),1,0) -> 0 | AD15: =IF(OR(AD$9=2,AD$9=4,AD$9=6),1,0) -> 0 | AE15: =IF(OR(AE$9=2,AE$9=4,AE$9=6),1,0) -> 1 | AF15: =IF(OR(AF$9=2,AF$9=4,AF$9=6),1,0) -> 0 | ... AI15: =IF(OR(AI$9=2,AI$9=4,AI$9=6),1,0) -> 1
B16: SETOR 6 | C16: SEG, QUA, SEX | D16: =VLOOKUP(B16,'Vias p Setor'!B:F,2,FALSE) -> 43.774 | E16: =F16*D16 -> 0 | F16: =SUM(G16:AJ16) -> 0
B17: SETOR 7 | C17: SEG, QUA, SEX | D17: =VLOOKUP(B17,'Vias p Setor'!B:F,2,FALSE) -> 53.756 | E17: =F17*D17 -> 645.072 | F17: =SUM(G17:AJ17) -> 12 | G17: =IF(OR(G$9=2,G$9=4,G$9=6),1,0) -> 1 | H17: =IF(OR(H$9=2,H$9=4,H$9=6),1,0) -> 0 | I17: =IF(OR(I$9=2,I$9=4,I$9=6),1,0) -> 0 | J17: =IF(OR(J$9=2,J$9=4,J$9=6),1,0) -> 1 | K17: =IF(OR(K$9=2,K$9=4,K$9=6),1,0) -> 0 | L17: =IF(OR(L$9=2,L$9=4,L$9=6),1,0) -> 1 | M17: =IF(OR(M$9=2,M$9=4,M$9=6),1,0) -> 0 | N17: =IF(OR(N$9=2,N$9=4,N$9=6),1,0) -> 1 | ... W17: =IF(OR(W$9=2,W$9=4,W$9=6),1,0) -> 0 | Y17: =IF(OR(Y$9=2,Y$9=4,Y$9=6),1,0) -> 0 | Z17: =IF(OR(Z$9=2,Z$9=4,Z$9=6),1,0) -> 1 | AA17: =IF(OR(AA$9=2,AA$9=4,AA$9=6),1,0) -> 0 | AB17: =IF(OR(AB$9=2,AB$9=4,AB$9=6),1,0) -> 1 | AC17: =IF(OR(AC$9=2,AC$9=4,AC$9=6),1,0) -> 0 | AD17: =IF(OR(AD$9=2,AD$9=4,AD$9=6),1,0) -> 0 | AE17: =IF(OR(AE$9=2,AE$9=4,AE$9=6),1,0) -> 1 | AF17: =IF(OR(AF$9=2,AF$9=4,AF$9=6),1,0) -> 0 | ... AI17: =IF(OR(AI$9=2,AI$9=4,AI$9=6),1,0) -> 1
B18: SETOR 8 | C18: TER, QUI , SÁB | D18: =VLOOKUP(B18,'Vias p Setor'!B:F,2,FALSE) -> 52.217 | E18: =F18*D18 -> 626.604 | F18: =SUM(G18:AJ18) -> 12 | G18: =IF(OR(G$9=3,G$9=5,G$9=7),1,0) -> 0 | H18: =IF(OR(H$9=3,H$9=5,H$9=7),1,0) -> 1 | I18: =IF(OR(I$9=3,I$9=5,I$9=7),1,0) -> 0 | J18: =IF(OR(J$9=3,J$9=5,J$9=7),1,0) -> 0 | K18: =IF(OR(K$9=3,K$9=5,K$9=7),1,0) -> 1 | L18: =IF(OR(L$9=3,L$9=5,L$9=7),1,0) -> 0 | M18: =IF(OR(M$9=3,M$9=5,M$9=7),1,0) -> 1 | N18: =IF(OR(N$9=3,N$9=5,N$9=7),1,0) -> 0 | ... W18: =IF(OR(W$9=3,W$9=5,W$9=7),1,0) -> 0 | Y18: =IF(OR(Y$9=3,Y$9=5,Y$9=7),1,0) -> 1 | Z18: =IF(OR(Z$9=3,Z$9=5,Z$9=7),1,0) -> 0 | AA18: =IF(OR(AA$9=3,AA$9=5,AA$9=7),1,0) -> 1 | AB18: =IF(OR(AB$9=3,AB$9=5,AB$9=7),1,0) -> 0 | AC18: =IF(OR(AC$9=3,AC$9=5,AC$9=7),1,0) -> 1 | AD18: =IF(OR(AD$9=3,AD$9=5,AD$9=7),1,0) -> 0 | AE18: =IF(OR(AE$9=3,AE$9=5,AE$9=7),1,0) -> 0 | AF18: =IF(OR(AF$9=3,AF$9=5,AF$9=7),1,0) -> 1 | ... AI18: =IF(OR(AI$9=3,AI$9=5,AI$9=7),1,0) -> 0
B19: SETOR 9 | C19: TER, QUI , SÁB | D19: =VLOOKUP(B19,'Vias p Setor'!B:F,2,FALSE) -> 43.513 | E19: =F19*D19 -> 0 | F19: =SUM(G19:AJ19) -> 0
B20: SETOR 10 | C20: TER, QUI , SÁB | D20: =VLOOKUP(B20,'Vias p Setor'!B:F,2,FALSE) -> 49.761 | E20: =F20*D20 -> 597.132 | F20: =SUM(G20:AJ20) -> 12 | G20: =IF(OR(G$9=3,G$9=5,G$9=7),1,0) -> 0 | H20: =IF(OR(H$9=3,H$9=5,H$9=7),1,0) -> 1 | I20: =IF(OR(I$9=3,I$9=5,I$9=7),1,0) -> 0 | J20: =IF(OR(J$9=3,J$9=5,J$9=7),1,0) -> 0 | K20: =IF(OR(K$9=3,K$9=5,K$9=7),1,0) -> 1 | L20: =IF(OR(L$9=3,L$9=5,L$9=7),1,0) -> 0 | M20: =IF(OR(M$9=3,M$9=5,M$9=7),1,0) -> 1 | N20: =IF(OR(N$9=3,N$9=5,N$9=7),1,0) -> 0 | ... W20: =IF(OR(W$9=3,W$9=5,W$9=7),1,0) -> 0 | Y20: =IF(OR(Y$9=3,Y$9=5,Y$9=7),1,0) -> 1 | Z20: =IF(OR(Z$9=3,Z$9=5,Z$9=7),1,0) -> 0 | AA20: =IF(OR(AA$9=3,AA$9=5,AA$9=7),1,0) -> 1 | AB20: =IF(OR(AB$9=3,AB$9=5,AB$9=7),1,0) -> 0 | AC20: =IF(OR(AC$9=3,AC$9=5,AC$9=7),1,0) -> 1 | AD20: =IF(OR(AD$9=3,AD$9=5,AD$9=7),1,0) -> 0 | AE20: =IF(OR(AE$9=3,AE$9=5,AE$9=7),1,0) -> 0 | AF20: =IF(OR(AF$9=3,AF$9=5,AF$9=7),1,0) -> 1 | ... AI20: =IF(OR(AI$9=3,AI$9=5,AI$9=7),1,0) -> 0
B21: SETOR 11 | C21: TER, QUI , SÁB | D21: =VLOOKUP(B21,'Vias p Setor'!B:F,2,FALSE) -> 47.038 | E21: =F21*D21 -> 0 | F21: =SUM(G21:AJ21) -> 0
B22: SETOR 12 | C22: TER, QUI , SÁB | D22: =VLOOKUP(B22,'Vias p Setor'!B:F,2,FALSE) -> 43.515 | E22: =F22*D22 -> 0 | F22: =SUM(G22:AJ22) -> 0
B23: SETOR 13 | C23: TER, QUI , SÁB | D23: =VLOOKUP(B23,'Vias p Setor'!B:F,2,FALSE) -> 48.881 | E23: =F23*D23 -> 0 | F23: =SUM(G23:AJ23) -> 0
B24: SETOR 14 | C24: TER, QUI , SÁB | D24: =VLOOKUP(B24,'Vias p Setor'!B:F,2,FALSE) -> 45.636 | E24: =F24*D24 -> 0 | F24: =SUM(G24:AJ24) -> 0
B27: TOTAL KM DE SARJETAS DA VIA: | D27: =ROUND(SUM(E11:E24),2) -> 3136.97
X29: Feriado

Sheet TabelaVarriçãoManual
A1: SERVIÇO | B1: DATA | C1: LOCAL | D1: TIPO DE EQUIPAMENTO | E1: UNIDADE | F1: QUANTIDADE | G1: OBSERVAÇÃO
A2: VARRIÇÃO MANUAL | B2: 1-set-26 | C2: 1 | D2: LUTOCAR | E2: KM | F2: 6.0519 | G2: 2 vezes na semana
A3: VARRIÇÃO MANUAL | B3: 1-set-26 | C3: 2 | D3: LUTOCAR | E3: KM | F3: 5.68152 | G3: 2 vezes na semana
A4: VARRIÇÃO MANUAL | B4: 1-set-26 | C4: 3 | D4: LUTOCAR | E4: KM | F4: 6.37664 | G4: 2 vezes na semana
A5: VARRIÇÃO MANUAL | B5: 1-set-26 | C5: 4 | D5: LUTOCAR | E5: KM | F5: 6.5455 | G5: 2 vezes na semana
A6: VARRIÇÃO MANUAL | B6: 1-set-26 | C6: 5 | D6: LUTOCAR | E6: KM | F6: 5.80924 | G6: 2 vezes na semana
A7: VARRIÇÃO MANUAL | B7: 1-set-26 | C7: 6 | D7: LUTOCAR | E7: KM | F7: 6.0586 | G7: 2 vezes na semana
A8: VARRIÇÃO MANUAL | B8: 1-set-26 | C8: 7 | D8: LUTOCAR | E8: KM | F8: 6.00108 | G8: 2 vezes na semana
A9: VARRIÇÃO MANUAL | B9: 1-set-26 | C9: 8 | D9: LUTOCAR | E9: KM | F9: 5.8184 | G9: 2 vezes na semana
A10: VARRIÇÃO MANUAL | B10: 1-set-26 | C10: 9 | D10: LUTOCAR | E10: KM | F10: 6.29898 | G10: 2 vezes na semana
A11: VARRIÇÃO MANUAL | B11: 1-set-26 | C11: 10 | D11: LUTOCAR | E11: KM | F11: 6.06128 | G11: 2 vezes na semana
A12: VARRIÇÃO MANUAL | B12: 1-set-26 | C12: 11 | D12: LUTOCAR | E12: KM | F12: 6.19618 | G12: 2 vezes na semana
A13: VARRIÇÃO MANUAL | B13: 1-set-26 | C13: 12 | D13: LUTOCAR | E13: KM | F13: 6.00986 | G13: 2 vezes na semana
... A1988: VARRIÇÃO MANUAL | B1988: 9-set-26 | C1988: 361 | D1988: LUTOCAR | E1988: KM | F1988: 5.81496 | G1988: 2 vezes na semana

Sheet Vias Var Man
D1: OBJETO: Contratação de empresa especializada para a prestação de “Serviços de limpeza pública urbana do município de Aparecida de Goiânia, Estado de Goiás, compreendendo os serviços de coleta domiciliar e comercial, varrição mecanizada, varrição manual, e equipe de serviços diversos de remoção de entulhos e materiais inservíveis, capina e raspagem”
D2: CONCORRÊNCIA PÚBLICA TIPO: MENOR PREÇO N° 012/2023
B7: SETORES X AVENIDAS E RUAS X FREQUÊNCIA
H8: 0
B9: ="MAPA DE APONTAMENTO DAS VIAS DA VARRIÇÃO MANUAL - "&#REF! -> #REF!
H10: 0
B11: Setor | C11: RUAS / AVENIDAS | D11: Frequencia | E11: Período | F11: Soma de Comprimento (Eixo -KM) | G11: Soma de Comprimento (Sarjeta -KM) | H11: 0
B12: 1 | C12: Avenida Aragoiânia | D12: 2 vezes na semana | E12: Diurno | F12: 0.57548 | G12: =F12*2 -> 1.15096 | H12: 6.0519
B13: 1 | C13: Rodovia GO-040 | D13: 2 vezes na semana | E13: Diurno | F13: 0.09193 | G13: =F13*2 -> 0.18386
B14: 1 | C14: Rua 1-C | D14: 2 vezes na semana | E14: Diurno | F14: 0.09313 | G14: =F14*2 -> 0.18626
B15: 1 | C15: Rua 28-C | D15: 2 vezes na semana | E15: Diurno | F15: 0.07331 | G15: =F15*2 -> 0.14662
B16: 1 | C16: Rua 2-C | D16: 2 vezes na semana | E16: Diurno | F16: 0.12603 | G16: =F16*2 -> 0.25206
B17: 1 | C17: Rua 3-C | D17: 2 vezes na semana | E17: Diurno | F17: 0.12964 | G17: =F17*2 -> 0.25928
B18: 1 | C18: Rua 5-C | D18: 2 vezes na semana | E18: Diurno | F18: 0.13792 | G18: =F18*2 -> 0.27584
B19: 1 | C19: Rua 5-E | D19: 2 vezes na semana | E19: Diurno | F19: 0.33965 | G19: =F19*2 -> 0.6793
B20: 1 | C20: Rua 6-C | D20: 2 vezes na semana | E20: Diurno | F20: 0.14001 | G20: =F20*2 -> 0.28002
B21: 1 | C21: Rua 7-C | D21: 2 vezes na semana | E21: Diurno | F21: 0.46286 | G21: =F21*2 -> 0.92572
B22: 1 | C22: Rua 8-C | D22: 2 vezes na semana | E22: Diurno | F22: 0.45669 | G22: =F22*2 -> 0.91338
B23: 1 | C23: Rua 9-C | D23: 2 vezes na semana | E23: Diurno | F23: 0.3993 | G23: =F23*2 -> 0.7986
B24: 2 | C24: Rua 10-C | D24: 2 vezes na semana | E24: Diurno | F24: 0.4441 | G24: =F24*2 -> 0.8882 | H24: 5.68152
B25: 2 | C25: Rua 11-C | D25: 2 vezes na semana | E25: Diurno | F25: 0.40025 | G25: =F25*2 -> 0.8005
B26: 2 | C26: Rua 12-C | D26: 2 vezes na semana | E26: Diurno | F26: 0.39979 | G26: =F26*2 -> 0.79958
B27: 2 | C27: Rua 13-C | D27: 2 vezes na semana | E27: Diurno | F27: 0.39618 | G27: =F27*2 -> 0.79236
B28: 2 | C28: Rua 14-C | D28: 2 vezes na semana | E28: Diurno | F28: 0.39426 | G28: =F28*2 -> 0.78852
B29: 2 | C29: Rua 29-C | D29: 2 vezes na semana | E29: Diurno | F29: 0.14288 | G29: =F29*2 -> 0.28576
B30: 2 | C30: Rua 2-E | D30: 2 vezes na semana | E30: Diurno | F30: 0.07453 | G30: =F30*2 -> 0.14906
B31: 2 | C31: Rua 30-C | D31: 2 vezes na semana | E31: Diurno | F31: 0.07035 | G31: =F31*2 -> 0.1407
B32: 2 | C32: Rua 31-C | D32: 2 vezes na semana | E32: Diurno | F32: 0.07113 | G32: =F32*2 -> 0.14226
B33: 2 | C33: Rua 5-E | D33: 2 vezes na semana | E33: Diurno | F33: 0.44729 | G33: =F33*2 -> 0.89458
B34: 3 | C34: Rua 16-C | D34: 2 vezes na semana | E34: Diurno | F34: 0.32873 | G34: =F34*2 -> 0.65746 | H34: 6.37664
B35: 3 | C35: Rua 17-C | D35: 2 vezes na semana | E35: Diurno | F35: 0.38766 | G35: =F35*2 -> 0.77532
B36: 3 | C36: Rua 18-C | D36: 2 vezes na semana | E36: Diurno | F36: 0.43536 | G36: =F36*2 -> 0.87072
B37: 3 | C37: Rua 19-C | D37: 2 vezes na semana | E37: Diurno | F37: 0.39176 | G37: =F37*2 -> 0.78352
B38: 3 | C38: Rua 20-C | D38: 2 vezes na semana | E38: Diurno | F38: 0.43465 | G38: =F38*2 -> 0.8693
B39: 3 | C39: Rua 21-C | D39: 2 vezes na semana | E39: Diurno | F39: 0.38575 | G39: =F39*2 -> 0.7715
B40: 3 | C40: Rua 32-C | D40: 2 vezes na semana | E40: Diurno | F40: 0.06754 | G40: =F40*2 -> 0.13508
B41: 3 | C41: Rua 33-C | D41: 2 vezes na semana | E41: Diurno | F41: 0.13861 | G41: =F41*2 -> 0.27722
B42: 3 | C42: Rua 34-C | D42: 2 vezes na semana | E42: Diurno | F42: 0.06983 | G42: =F42*2 -> 0.13966
B43: 3 | C43: Rua 5-E | D43: 2 vezes na semana | E43: Diurno | F43: 0.54843 | G43: =F43*2 -> 1.09686
B44: 4 | C44: Rua 18-D | D44: 2 vezes na semana | E44: Diurno | F44: 0.58457 | G44: =F44*2 -> 1.16914 | H44: 6.5455
...

Sheet MAPA VARRIÇÃO MANUAL
F2: OBJETO: | G2: CONTRATAÇÃO DE EMPRESA ESPECIALIZADA EM SERVIÇOS DE LIMPEZA URBANA – SLU E COLETA CONVENCIONAL E MECANIZADA, TRANSPORTE E DESTINAÇÃO FINAL DE RESÍDUOS DOMICILIARES PORTA A PORTA, NO MUNICÍPIO DE APARECIDA DE GOIÂNIA - GO. | AM2: CONTRATAÇÃO DE EMPRESA ESPECIALIZADA EM SERVIÇOS DE LIMPEZA URBANA – SLU E COLETA CONVENCIONAL E MECANIZADA, TRANSPORTE E DESTINAÇÃO FINAL DE RESÍDUOS DOMICILIARES PORTA A PORTA, NO MUNICÍPIO DE APARECIDA DE GOIÂNIA - GO.
F3: CONCORRÊNCIA PÚBLICA TIPO: MENOR PREÇO N° 012/2023
F4: CONTRATO: | I4: =#REF! -> #REF! | L4: CONTRATADA: CONSÓRCIO SQ APARECIDA SUSTENTÁVEL - CNPJ.: 56.309.119/0001-03
F5: DATA: | I5: =#REF! -> #REF! | L5: PERÍODO: | N5: =#REF! -> #REF!
B6: ="ITEM - MAPA DE APONTAMENTO DOS SERVIÇOS DE VARRIÇÃO MANUAL DE VIAS - SARJETAS - "&#REF! -> #REF!
G8: =WEEKDAY(G9) -> 6 | H8: =WEEKDAY(H9) -> 7 | I8: =WEEKDAY(I9) -> 1 | J8: =WEEKDAY(J9) -> 2 | K8: =WEEKDAY(K9) -> 3 | L8: =WEEKDAY(L9) -> 4 | M8: =WEEKDAY(M9) -> 5 | N8: =WEEKDAY(N9) -> 6 | ... AK8: =WEEKDAY(AK9) -> 5
B9: SETOR | C9: FREQUÊNCIA | D9: COMP SARJETA (KM) | E9: TOTAL KM POR MÊS | F9: NÚMERO DE EXECUÇÕES | G9: 25-set-26 | H9: 26-set-26 | I9: 27-set-26 | J9: 28-set-26 | K9: 29-set-26 | L9: 30-set-26 | M9: 1-out-26 | N9: 2-out-26 | O9: 3-out-26 | P9: 4-out-26 | Q9: 5-out-26 | R9: 6-out-26 | S9: 7-out-26 | T9: 8-out-26 | U9: 9-out-26 | V9: 10-out-26 | W9: 11-out-26 | X9: 12-out-26 | Y9: 13-out-26 | Z9: 14-out-26 | AA9: 15-out-26 | AB9: 16-out-26 | AC9: 17-out-26 | AD9: 18-out-26 | AE9: 19-out-26 | AF9: 20-out-26 | AG9: 21-out-26 | AH9: 22-out-26 | AI9: 23-out-26 | AJ9: 24-out-26 | AK9: 24-set-26 | AO9: 46259 | AP9: =AO9+1 -> 46260 | AQ9: =AP9+1 -> 46261 | AR9: =AQ9+1 -> 46262 | AS9: =AR9+1 -> 46263 | AT9: =AS9+1 -> 46264 | AU9: =AT9+1 -> 46265 | AV9: =AU9+1 -> 46266 | AW9: =AV9+1 -> 46267 | ... BS9: =BR9+1 -> 46289
B10: 1 | C10: =INDEX('Vias Var Man'!$D$12:$D$3949,MATCH('MAPA VARRIÇÃO MANUAL'!B10,'Vias Var Man'!$B$12:$B$3949)) -> 2 vezes na semana | D10: =VLOOKUP(B10,'Vias Var Man'!$B$12:$H$3949,7,FALSE) -> 6.0519 | E10: =F10*D10 -> 54.4671 | F10: =SUM(G10:AK10) -> 9 | G10: =IF(OR(WEEKDAY(G$9,1)=3,WEEKDAY(G$9,1)=6),1,0) -> 1 | H10: =IF(OR(WEEKDAY(H$9,1)=3,WEEKDAY(H$9,1)=6),1,0) -> 0 | I10: =IF(OR(WEEKDAY(I$9,1)=3,WEEKDAY(I$9,1)=6),1,0) -> 0 | J10: =IF(OR(WEEKDAY(J$9,1)=3,WEEKDAY(J$9,1)=6),1,0) -> 0 | K10: =IF(OR(WEEKDAY(K$9,1)=3,WEEKDAY(K$9,1)=6),1,0) -> 1 | L10: =IF(OR(WEEKDAY(L$9,1)=3,WEEKDAY(L$9,1)=6),1,0) -> 0 | M10: =IF(OR(WEEKDAY(M$9,1)=3,WEEKDAY(M$9,1)=6),1,0) -> 0 | N10: =IF(OR(WEEKDAY(N$9,1)=3,WEEKDAY(N$9,1)=6),1,0) -> 1 | ... AI10: =IF(OR(WEEKDAY(AI$9,1)=3,WEEKDAY(AI$9,1)=6),1,0) -> 1
B11: 2 | C11: =INDEX('Vias Var Man'!$D$12:$D$3949,MATCH('MAPA VARRIÇÃO MANUAL'!B11,'Vias Var Man'!$B$12:$B$3949)) -> 2 vezes na semana | D11: =VLOOKUP(B11,'Vias Var Man'!$B$12:$H$3949,7,FALSE) -> 5.68152 | E11: =F11*D11 -> 51.13368 | F11: =SUM(G11:AK11) -> 9 | G11: =IF(OR(WEEKDAY(G$9,1)=3,WEEKDAY(G$9,1)=6),1,0) -> 1 | H11: =IF(OR(WEEKDAY(H$9,1)=3,WEEKDAY(H$9,1)=6),1,0) -> 0 | I11: =IF(OR(WEEKDAY(I$9,1)=3,WEEKDAY(I$9,1)=6),1,0) -> 0 | J11: =IF(OR(WEEKDAY(J$9,1)=3,WEEKDAY(J$9,1)=6),1,0) -> 0 | K11: =IF(OR(WEEKDAY(K$9,1)=3,WEEKDAY(K$9,1)=6),1,0) -> 1 | L11: =IF(OR(WEEKDAY(L$9,1)=3,WEEKDAY(L$9,1)=6),1,0) -> 0 | M11: =IF(OR(WEEKDAY(M$9,1)=3,WEEKDAY(M$9,1)=6),1,0) -> 0 | N11: =IF(OR(WEEKDAY(N$9,1)=3,WEEKDAY(N$9,1)=6),1,0) -> 1 | ... AI11: =IF(OR(WEEKDAY(AI$9,1)=3,WEEKDAY(AI$9,1)=6),1,0) -> 1 | AL11: =IF(OR(AL$8=2,AL$8=4,AL$8=6),1,0) -> 0
B12: 3 | C12: =INDEX('Vias Var Man'!$D$12:$D$3949,MATCH('MAPA VARRIÇÃO MANUAL'!B12,'Vias Var Man'!$B$12:$B$3949)) -> 2 vezes na semana | D12: =VLOOKUP(B12,'Vias Var Man'!$B$12:$H$3949,7,FALSE) -> 6.37664 | E12: =F12*D12 -> 57.38976 | F12: =SUM(G12:AK12) -> 9 | G12: =IF(OR(WEEKDAY(G$9,1)=3,WEEKDAY(G$9,1)=6),1,0) -> 1 | H12: =IF(OR(WEEKDAY(H$9,1)=3,WEEKDAY(H$9,1)=6),1,0) -> 0 | I12: =IF(OR(WEEKDAY(I$9,1)=3,WEEKDAY(I$9,1)=6),1,0) -> 0 | J12: =IF(OR(WEEKDAY(J$9,1)=3,WEEKDAY(J$9,1)=6),1,0) -> 0 | K12: =IF(OR(WEEKDAY(K$9,1)=3,WEEKDAY(K$9,1)=6),1,0) -> 1 | L12: =IF(OR(WEEKDAY(L$9,1)=3,WEEKDAY(L$9,1)=6),1,0) -> 0 | M12: =IF(OR(WEEKDAY(M$9,1)=3,WEEKDAY(M$9,1)=6),1,0) -> 0 | N12: =IF(OR(WEEKDAY(N$9,1)=3,WEEKDAY(N$9,1)=6),1,0) -> 1 | ... AI12: =IF(OR(WEEKDAY(AI$9,1)=3,WEEKDAY(AI$9,1)=6),1,0) -> 1
B13: 4 | C13: =INDEX('Vias Var Man'!$D$12:$D$3949,MATCH('MAPA VARRIÇÃO MANUAL'!B13,'Vias Var Man'!$B$12:$B$3949)) -> 2 vezes na semana | D13: =VLOOKUP(B13,'Vias Var Man'!$B$12:$H$3949,7,FALSE) -> 6.5455 | E13: =F13*D13 -> 58.9095 | F13: =SUM(G13:AK13) -> 9 | G13: =IF(OR(WEEKDAY(G$9,1)=3,WEEKDAY(G$9,1)=6),1,0) -> 1 | H13: =IF(OR(WEEKDAY(H$9,1)=3,WEEKDAY(H$9,1)=6),1,0) -> 0 | I13: =IF(OR(WEEKDAY(I$9,1)=3,WEEKDAY(I$9,1)=6),1,0) -> 0 | J13: =IF(OR(WEEKDAY(J$9,1)=3,WEEKDAY(J$9,1)=6),1,0) -> 0 | K13: =IF(OR(WEEKDAY(K$9,1)=3,WEEKDAY(K$9,1)=6),1,0) -> 1 | L13: =IF(OR(WEEKDAY(L$9,1)=3,WEEKDAY(L$9,1)=6),1,0) -> 0 | M13: =IF(OR(WEEKDAY(M$9,1)=3,WEEKDAY(M$9,1)=6),1,0) -> 0 | N13: =IF(OR(WEEKDAY(N$9,1)=3,WEEKDAY(N$9,1)=6),1,0) -> 1 | ... AI13: =IF(OR(WEEKDAY(AI$9,1)=3,WEEKDAY(AI$9,1)=6),1,0) -> 1 | AL13: =IF(OR(AL$8=2,AL$8=4,AL$8=6),1,0) -> 0
B14: 5 | C14: =INDEX('Vias Var Man'!$D$12:$D$3949,MATCH('MAPA VARRIÇÃO MANUAL'!B14,'Vias Var Man'!$B$12:$B$3949)) -> 2 vezes na semana | D14: =VLOOKUP(B14,'Vias Var Man'!$B$12:$H$3949,7,FALSE) -> 5.80924 | E14: =F14*D14 -> 52.28316 | F14: =SUM(G14:AK14) -> 9 | G14: =IF(OR(WEEKDAY(G$9,1)=3,WEEKDAY(G$9,1)=6),1,0) -> 1 | H14: =IF(OR(WEEKDAY(H$9,1)=3,WEEKDAY(H$9,1)=6),1,0) -> 0 | I14: =IF(OR(WEEKDAY(I$9,1)=3,WEEKDAY(I$9,1)=6),1,0) -> 0 | J14: =IF(OR(WEEKDAY(J$9,1)=3,WEEKDAY(J$9,1)=6),1,0) -> 0 | K14: =IF(OR(WEEKDAY(K$9,1)=3,WEEKDAY(K$9,1)=6),1,0) -> 1 | L14: =IF(OR(WEEKDAY(L$9,1)=3,WEEKDAY(L$9,1)=6),1,0) -> 0 | M14: =IF(OR(WEEKDAY(M$9,1)=3,WEEKDAY(M$9,1)=6),1,0) -> 0 | N14: =IF(OR(WEEKDAY(N$9,1)=3,WEEKDAY(N$9,1)=6),1,0) -> 1 | ... AI14: =IF(OR(WEEKDAY(AI$9,1)=3,WEEKDAY(AI$9,1)=6),1,0) -> 1
B15: 6 | C15: =INDEX('Vias Var Man'!$D$12:$D$3949,MATCH('MAPA VARRIÇÃO MANUAL'!B15,'Vias Var Man'!$B$12:$B$3949)) -> 2 vezes na semana | D15: =VLOOKUP(B15,'Vias Var Man'!$B$12:$H$3949,7,FALSE) -> 6.0586 | E15: =F15*D15 -> 54.5274 | F15: =SUM(G15:AK15) -> 9 | G15: =IF(OR(WEEKDAY(G$9,1)=3,WEEKDAY(G$9,1)=6),1,0) -> 1 | H15: =IF(OR(WEEKDAY(H$9,1)=3,WEEKDAY(H$9,1)=6),1,0) -> 0 | I15: =IF(OR(WEEKDAY(I$9,1)=3,WEEKDAY(I$9,1)=6),1,0) -> 0 | J15: =IF(OR(WEEKDAY(J$9,1)=3,WEEKDAY(J$9,1)=6),1,0) -> 0 | K15: =IF(OR(WEEKDAY(K$9,1)=3,WEEKDAY(K$9,1)=6),1,0) -> 1 | L15: =IF(OR(WEEKDAY(L$9,1)=3,WEEKDAY(L$9,1)=6),1,0) -> 0 | M15: =IF(OR(WEEKDAY(M$9,1)=3,WEEKDAY(M$9,1)=6),1,0) -> 0 | N15: =IF(OR(WEEKDAY(N$9,1)=3,WEEKDAY(N$9,1)=6),1,0) -> 1 | ... AI15: =IF(OR(WEEKDAY(AI$9,1)=3,WEEKDAY(AI$9,1)=6),1,0) -> 1 | AL15: =IF(OR(AL$8=2,AL$8=4,AL$8=6),1,0) -> 0
B16: 7 | C16: =INDEX('Vias Var Man'!$D$12:$D$3949,MATCH('MAPA VARRIÇÃO MANUAL'!B16,'Vias Var Man'!$B$12:$B$3949)) -> 2 vezes na semana | D16: =VLOOKUP(B16,'Vias Var Man'!$B$12:$H$3949,7,FALSE) -> 6.00108 | E16: =F16*D16 -> 54.00972 | F16: =SUM(G16:AK16) -> 9 | G16: =IF(OR(WEEKDAY(G$9,1)=3,WEEKDAY(G$9,1)=6),1,0) -> 1 | H16: =IF(OR(WEEKDAY(H$9,1)=3,WEEKDAY(H$9,1)=6),1,0) -> 0 | I16: =IF(OR(WEEKDAY(I$9,1)=3,WEEKDAY(I$9,1)=6),1,0) -> 0 | J16: =IF(OR(WEEKDAY(J$9,1)=3,WEEKDAY(J$9,1)=6),1,0) -> 0 | K16: =IF(OR(WEEKDAY(K$9,1)=3,WEEKDAY(K$9,1)=6),1,0) -> 1 | L16: =IF(OR(WEEKDAY(L$9,1)=3,WEEKDAY(L$9,1)=6),1,0) -> 0 | M16: =IF(OR(WEEKDAY(M$9,1)=3,WEEKDAY(M$9,1)=6),1,0) -> 0 | N16: =IF(OR(WEEKDAY(N$9,1)=3,WEEKDAY(N$9,1)=6),1,0) -> 1 | ... AI16: =IF(OR(WEEKDAY(AI$9,1)=3,WEEKDAY(AI$9,1)=6),1,0) -> 1
B17: 8 | C17: =INDEX('Vias Var Man'!$D$12:$D$3949,MATCH('MAPA VARRIÇÃO MANUAL'!B17,'Vias Var Man'!$B$12:$B$3949)) -> 2 vezes na semana | D17: =VLOOKUP(B17,'Vias Var Man'!$B$12:$H$3949,7,FALSE) -> 5.8184 | E17: =F17*D17 -> 52.3656 | F17: =SUM(G17:AK17) -> 9 | G17: =IF(OR(WEEKDAY(G$9,1)=3,WEEKDAY(G$9,1)=6),1,0) -> 1 | H17: =IF(OR(WEEKDAY(H$9,1)=3,WEEKDAY(H$9,1)=6),1,0) -> 0 | I17: =IF(OR(WEEKDAY(I$9,1)=3,WEEKDAY(I$9,1)=6),1,0) -> 0 | J17: =IF(OR(WEEKDAY(J$9,1)=3,WEEKDAY(J$9,1)=6),1,0) -> 0 | K17: =IF(OR(WEEKDAY(K$9,1)=3,WEEKDAY(K$9,1)=6),1,0) -> 1 | L17: =IF(OR(WEEKDAY(L$9,1)=3,WEEKDAY(L$9,1)=6),1,0) -> 0 | M17: =IF(OR(WEEKDAY(M$9,1)=3,WEEKDAY(M$9,1)=6),1,0) -> 0 | N17: =IF(OR(WEEKDAY(N$9,1)=3,WEEKDAY(N$9,1)=6),1,0) -> 1 | ... AI17: =IF(OR(WEEKDAY(AI$9,1)=3,WEEKDAY(AI$9,1)=6),1,0) -> 1 | AL17: =IF(OR(AL$8=2,AL$8=4,AL$8=6),1,0) -> 0
B18: 9 | C18: =INDEX('Vias Var Man'!$D$12:$D$3949,MATCH('MAPA VARRIÇÃO MANUAL'!B18,'Vias Var Man'!$B$12:$B$3949)) -> 2 vezes na semana | D18: =VLOOKUP(B18,'Vias Var Man'!$B$12:$H$3949,7,FALSE) -> 6.29898 | E18: =F18*D18 -> 56.69082 | F18: =SUM(G18:AK18) -> 9 | G18: =IF(OR(WEEKDAY(G$9,1)=3,WEEKDAY(G$9,1)=6),1,0) -> 1 | H18: =IF(OR(WEEKDAY(H$9,1)=3,WEEKDAY(H$9,1)=6),1,0) -> 0 | I18: =IF(OR(WEEKDAY(I$9,1)=3,WEEKDAY(I$9,1)=6),1,0) -> 0 | J18: =IF(OR(WEEKDAY(J$9,1)=3,WEEKDAY(J$9,1)=6),1,0) -> 0 | K18: =IF(OR(WEEKDAY(K$9,1)=3,WEEKDAY(K$9,1)=6),1,0) -> 1 | L18: =IF(OR(WEEKDAY(L$9,1)=3,WEEKDAY(L$9,1)=6),1,0) -> 0 | M18: =IF(OR(WEEKDAY(M$9,1)=3,WEEKDAY(M$9,1)=6),1,0) -> 0 | N18: =IF(OR(WEEKDAY(N$9,1)=3,WEEKDAY(N$9,1)=6),1,0) -> 1 | ... AI18: =IF(OR(WEEKDAY(AI$9,1)=3,WEEKDAY(AI$9,1)=6),1,0) -> 1
B19: 10 | C19: =INDEX('Vias Var Man'!$D$12:$D$3949,MATCH('MAPA VARRIÇÃO MANUAL'!B19,'Vias Var Man'!$B$12:$B$3949)) -> 2 vezes na semana | D19: =VLOOKUP(B19,'Vias Var Man'!$B$12:$H$3949,7,FALSE) -> 6.06128 | E19: =F19*D19 -> 54.55152 | F19: =SUM(G19:AK19) -> 9 | G19: =IF(OR(WEEKDAY(G$9,1)=3,WEEKDAY(G$9,1)=6),1,0) -> 1 | H19: =IF(OR(WEEKDAY(H$9,1)=3,WEEKDAY(H$9,1)=6),1,0) -> 0 | I19: =IF(OR(WEEKDAY(I$9,1)=3,WEEKDAY(I$9,1)=6),1,0) -> 0 | J19: =IF(OR(WEEKDAY(J$9,1)=3,WEEKDAY(J$9,1)=6),1,0) -> 0 | K19: =IF(OR(WEEKDAY(K$9,1)=3,WEEKDAY(K$9,1)=6),1,0) -> 1 | L19: =IF(OR(WEEKDAY(L$9,1)=3,WEEKDAY(L$9,1)=6),1,0) -> 0 | M19: =IF(OR(WEEKDAY(M$9,1)=3,WEEKDAY(M$9,1)=6),1,0) -> 0 | N19: =IF(OR(WEEKDAY(N$9,1)=3,WEEKDAY(N$9,1)=6),1,0) -> 1 | ... AI19: =IF(OR(WEEKDAY(AI$9,1)=3,WEEKDAY(AI$9,1)=6),1,0) -> 1 | AL19: =IF(OR(AL$8=2,AL$8=4,AL$8=6),1,0) -> 0
B20: 11 | C20: =INDEX('Vias Var Man'!$D$12:$D$3949,MATCH('MAPA VARRIÇÃO MANUAL'!B20,'Vias Var Man'!$B$12:$B$3949)) -> 2 vezes na semana | D20: =VLOOKUP(B20,'Vias Var Man'!$B$12:$H$3949,7,FALSE) -> 6.19618 | E20: =F20*D20 -> 55.76562 | F20: =SUM(G20:AK20) -> 9 | G20: =IF(OR(WEEKDAY(G$9,1)=3,WEEKDAY(G$9,1)=6),1,0) -> 1 | H20: =IF(OR(WEEKDAY(H$9,1)=3,WEEKDAY(H$9,1)=6),1,0) -> 0 | I20: =IF(OR(WEEKDAY(I$9,1)=3,WEEKDAY(I$9,1)=6),1,0) -> 0 | J20: =IF(OR(WEEKDAY(J$9,1)=3,WEEKDAY(J$9,1)=6),1,0) -> 0 | K20: =IF(OR(WEEKDAY(K$9,1)=3,WEEKDAY(K$9,1)=6),1,0) -> 1 | L20: =IF(OR(WEEKDAY(L$9,1)=3,WEEKDAY(L$9,1)=6),1,0) -> 0 | M20: =IF(OR(WEEKDAY(M$9,1)=3,WEEKDAY(M$9,1)=6),1,0) -> 0 | N20: =IF(OR(WEEKDAY(N$9,1)=3,WEEKDAY(N$9,1)=6),1,0) -> 1 | ... AI20: =IF(OR(WEEKDAY(AI$9,1)=3,WEEKDAY(AI$9,1)=6),1,0) -> 1
B21: 12 | C21: =INDEX('Vias Var Man'!$D$12:$D$3949,MATCH('MAPA VARRIÇÃO MANUAL'!B21,'Vias Var Man'!$B$12:$B$3949)) -> 2 vezes na semana | D21: =VLOOKUP(B21,'Vias Var Man'!$B$12:$H$3949,7,FALSE) -> 6.00986 | E21: =F21*D21 -> 54.08874 | F21: =SUM(G21:AK21) -> 9 | G21: =IF(OR(WEEKDAY(G$9,1)=3,WEEKDAY(G$9,1)=6),1,0) -> 1 | H21: =IF(OR(WEEKDAY(H$9,1)=3,WEEKDAY(H$9,1)=6),1,0) -> 0 | I21: =IF(OR(WEEKDAY(I$9,1)=3,WEEKDAY(I$9,1)=6),1,0) -> 0 | J21: =IF(OR(WEEKDAY(J$9,1)=3,WEEKDAY(J$9,1)=6),1,0) -> 0 | K21: =IF(OR(WEEKDAY(K$9,1)=3,WEEKDAY(K$9,1)=6),1,0) -> 1 | L21: =IF(OR(WEEKDAY(L$9,1)=3,WEEKDAY(L$9,1)=6),1,0) -> 0 | M21: =IF(OR(WEEKDAY(M$9,1)=3,WEEKDAY(M$9,1)=6),1,0) -> 0 | N21: =IF(OR(WEEKDAY(N$9,1)=3,WEEKDAY(N$9,1)=6),1,0) -> 1 | ... AI21: =IF(OR(WEEKDAY(AI$9,1)=3,WEEKDAY(AI$9,1)=6),1,0) -> 1 | AL21: =IF(OR(AL$8=2,AL$8=4,AL$8=6),1,0) -> 0
B22: 13 | C22: =INDEX('Vias Var Man'!$D$12:$D$3949,MATCH('MAPA VARRIÇÃO MANUAL'!B22,'Vias Var Man'!$B$12:$B$3949)) -> 2 vezes na semana | D22: =VLOOKUP(B22,'Vias Var Man'!$B$12:$H$3949,7,FALSE) -> 6.3553 | E22: =F22*D22 -> 57.1977 | F22: =SUM(G22:AK22) -> 9 | G22: =IF(OR(WEEKDAY(G$9,1)=3,WEEKDAY(G$9,1)=6),1,0) -> 1 | H22: =IF(OR(WEEKDAY(H$9,1)=3,WEEKDAY(H$9,1)=6),1,0) -> 0 | I22: =IF(OR(WEEKDAY(I$9,1)=3,WEEKDAY(I$9,1)=6),1,0) -> 0 | J22: =IF(OR(WEEKDAY(J$9,1)=3,WEEKDAY(J$9,1)=6),1,0) -> 0 | K22: =IF(OR(WEEKDAY(K$9,1)=3,WEEKDAY(K$9,1)=6),1,0) -> 1 | L22: =IF(OR(WEEKDAY(L$9,1)=3,WEEKDAY(L$9,1)=6),1,0) -> 0 | M22: =IF(OR(WEEKDAY(M$9,1)=3,WEEKDAY(M$9,1)=6),1,0) -> 0 | N22: =IF(OR(WEEKDAY(N$9,1)=3,WEEKDAY(N$9,1)=6),1,0) -> 1 | ... AI22: =IF(OR(WEEKDAY(AI$9,1)=3,WEEKDAY(AI$9,1)=6),1,0) -> 1
B23: 14 | C23: =INDEX('Vias Var Man'!$D$12:$D$3949,MATCH('MAPA VARRIÇÃO MANUAL'!B23,'Vias Var Man'!$B$12:$B$3949)) -> 2 vezes na semana | D23: =VLOOKUP(B23,'Vias Var Man'!$B$12:$H$3949,7,FALSE) -> 6.22764 | E23: =F23*D23 -> 56.04876 | F23: =SUM(G23:AK23) -> 9 | G23: =IF(OR(WEEKDAY(G$9,1)=3,WEEKDAY(G$9,1)=6),1,0) -> 1 | H23: =IF(OR(WEEKDAY(H$9,1)=3,WEEKDAY(H$9,1)=6),1,0) -> 0 | I23: =IF(OR(WEEKDAY(I$9,1)=3,WEEKDAY(I$9,1)=6),1,0) -> 0 | J23: =IF(OR(WEEKDAY(J$9,1)=3,WEEKDAY(J$9,1)=6),1,0) -> 0 | K23: =IF(OR(WEEKDAY(K$9,1)=3,WEEKDAY(K$9,1)=6),1,0) -> 1 | L23: =IF(OR(WEEKDAY(L$9,1)=3,WEEKDAY(L$9,1)=6),1,0) -> 0 | M23: =IF(OR(WEEKDAY(M$9,1)=3,WEEKDAY(M$9,1)=6),1,0) -> 0 | N23: =IF(OR(WEEKDAY(N$9,1)=3,WEEKDAY(N$9,1)=6),1,0) -> 1 | ... AI23: =IF(OR(WEEKDAY(AI$9,1)=3,WEEKDAY(AI$9,1)=6),1,0) -> 1 | AL23: =IF(OR(AL$8=2,AL$8=4,AL$8=6),1,0) -> 0
B24: 15 | C24: =INDEX('Vias Var Man'!$D$12:$D$3949,MATCH('MAPA VARRIÇÃO MANUAL'!B24,'Vias Var Man'!$B$12:$B$3949)) -> 2 vezes na semana | D24: =VLOOKUP(B24,'Vias Var Man'!$B$12:$H$3949,7,FALSE) -> 6.52312 | E24: =F24*D24 -> 58.70808 | F24: =SUM(G24:AK24) -> 9 | G24: =IF(OR(WEEKDAY(G$9,1)=3,WEEKDAY(G$9,1)=6),1,0) -> 1 | H24: =IF(OR(WEEKDAY(H$9,1)=3,WEEKDAY(H$9,1)=6),1,0) -> 0 | I24: =IF(OR(WEEKDAY(I$9,1)=3,WEEKDAY(I$9,1)=6),1,0) -> 0 | J24: =IF(OR(WEEKDAY(J$9,1)=3,WEEKDAY(J$9,1)=6),1,0) -> 0 | K24: =IF(OR(WEEKDAY(K$9,1)=3,WEEKDAY(K$9,1)=6),1,0) -> 1 | L24: =IF(OR(WEEKDAY(L$9,1)=3,WEEKDAY(L$9,1)=6),1,0) -> 0 | M24: =IF(OR(WEEKDAY(M$9,1)=3,WEEKDAY(M$9,1)=6),1,0) -> 0 | N24: =IF(OR(WEEKDAY(N$9,1)=3,WEEKDAY(N$9,1)=6),1,0) -> 1 | ... AI24: =IF(OR(WEEKDAY(AI$9,1)=3,WEEKDAY(AI$9,1)=6),1,0) -> 1
B25: 16 | C25: =INDEX('Vias Var Man'!$D$12:$D$3949,MATCH('MAPA VARRIÇÃO MANUAL'!B25,'Vias Var Man'!$B$12:$B$3949)) -> 2 vezes na semana | D25: =VLOOKUP(B25,'Vias Var Man'!$B$12:$H$3949,7,FALSE) -> 6.524 | E25: =F25*D25 -> 58.716 | F25: =SUM(G25:AK25) -> 9 | G25: =IF(OR(WEEKDAY(G$9,1)=3,WEEKDAY(G$9,1)=6),1,0) -> 1 | H25: =IF(OR(WEEKDAY(H$9,1)=3,WEEKDAY(H$9,1)=6),1,0) -> 0 | I25: =IF(OR(WEEKDAY(I$9,1)=3,WEEKDAY(I$9,1)=6),1,0) -> 0 | J25: =IF(OR(WEEKDAY(J$9,1)=3,WEEKDAY(J$9,1)=6),1,0) -> 0 | K25: =IF(OR(WEEKDAY(K$9,1)=3,WEEKDAY(K$9,1)=6),1,0) -> 1 | L25: =IF(OR(WEEKDAY(L$9,1)=3,WEEKDAY(L$9,1)=6),1,0) -> 0 | M25: =IF(OR(WEEKDAY(M$9,1)=3,WEEKDAY(M$9,1)=6),1,0) -> 0 | N25: =IF(OR(WEEKDAY(N$9,1)=3,WEEKDAY(N$9,1)=6),1,0) -> 1 | ... AI25: =IF(OR(WEEKDAY(AI$9,1)=3,WEEKDAY(AI$9,1)=6),1,0) -> 1 | AL25: =IF(OR(AL$8=2,AL$8=4,AL$8=6),1,0) -> 0
B26: 17 | C26: =INDEX('Vias Var Man'!$D$12:$D$3949,MATCH('MAPA VARRIÇÃO MANUAL'!B26,'Vias Var Man'!$B$12:$B$3949)) -> 2 vezes na semana | D26: =VLOOKUP(B26,'Vias Var Man'!$B$12:$H$3949,7,FALSE) -> 6.00252 | E26: =F26*D26 -> 54.02268 | F26: =SUM(G26:AK26) -> 9 | G26: =IF(OR(WEEKDAY(G$9,1)=3,WEEKDAY(G$9,1)=6),1,0) -> 1 | H26: =IF(OR(WEEKDAY(H$9,1)=3,WEEKDAY(H$9,1)=6),1,0) -> 0 | I26: =IF(OR(WEEKDAY(I$9,1)=3,WEEKDAY(I$9,1)=6),1,0) -> 0 | J26: =IF(OR(WEEKDAY(J$9,1)=3,WEEKDAY(J$9,1)=6),1,0) -> 0 | K26: =IF(OR(WEEKDAY(K$9,1)=3,WEEKDAY(K$9,1)=6),1,0) -> 1 | L26: =IF(OR(WEEKDAY(L$9,1)=3,WEEKDAY(L$9,1)=6),1,0) -> 0 | M26: =IF(OR(WEEKDAY(M$9,1)=3,WEEKDAY(M$9,1)=6),1,0) -> 0 | N26: =IF(OR(WEEKDAY(N$9,1)=3,WEEKDAY(N$9,1)=6),1,0) -> 1 | ... AI26: =IF(OR(WEEKDAY(AI$9,1)=3,WEEKDAY(AI$9,1)=6),1,0) -> 1
B27: 18 | C27: =INDEX('Vias Var Man'!$D$12:$D$3949,MATCH('MAPA VARRIÇÃO MANUAL'!B27,'Vias Var Man'!$B$12:$B$3949)) -> 2 vezes na semana | D27: =VLOOKUP(B27,'Vias Var Man'!$B$12:$H$3949,7,FALSE) -> 6.0191 | E27: =F27*D27 -> 54.1719 | F27: =SUM(G27:AK27) -> 9 | G27: =IF(OR(WEEKDAY(G$9,1)=3,WEEKDAY(G$9,1)=6),1,0) -> 1 | H27: =IF(OR(WEEKDAY(H$9,1)=3,WEEKDAY(H$9,1)=6),1,0) -> 0 | I27: =IF(OR(WEEKDAY(I$9,1)=3,WEEKDAY(I$9,1)=6),1,0) -> 0 | J27: =IF(OR(WEEKDAY(J$9,1)=3,WEEKDAY(J$9,1)=6),1,0) -> 0 | K27: =IF(OR(WEEKDAY(K$9,1)=3,WEEKDAY(K$9,1)=6),1,0) -> 1 | L27: =IF(OR(WEEKDAY(L$9,1)=3,WEEKDAY(L$9,1)=6),1,0) -> 0 | M27: =IF(OR(WEEKDAY(M$9,1)=3,WEEKDAY(M$9,1)=6),1,0) -> 0 | N27: =IF(OR(WEEKDAY(N$9,1)=3,WEEKDAY(N$9,1)=6),1,0) -> 1 | ... AI27: =IF(OR(WEEKDAY(AI$9,1)=3,WEEKDAY(AI$9,1)=6),1,0) -> 1 | AL27: =IF(OR(AL$8=2,AL$8=4,AL$8=6),1,0) -> 0
B28: 19 | C28: =INDEX('Vias Var Man'!$D$12:$D$3949,MATCH('MAPA VARRIÇÃO MANUAL'!B28,'Vias Var Man'!$B$12:$B$3949)) -> 2 vezes na semana | D28: =VLOOKUP(B28,'Vias Var Man'!$B$12:$H$3949,7,FALSE) -> 6.3929 | E28: =F28*D28 -> 57.5361 | F28: =SUM(G28:AK28) -> 9 | G28: =IF(OR(WEEKDAY(G$9,1)=3,WEEKDAY(G$9,1)=6),1,0) -> 1 | H28: =IF(OR(WEEKDAY(H$9,1)=3,WEEKDAY(H$9,1)=6),1,0) -> 0 | I28: =IF(OR(WEEKDAY(I$9,1)=3,WEEKDAY(I$9,1)=6),1,0) -> 0 | J28: =IF(OR(WEEKDAY(J$9,1)=3,WEEKDAY(J$9,1)=6),1,0) -> 0 | K28: =IF(OR(WEEKDAY(K$9,1)=3,WEEKDAY(K$9,1)=6),1,0) -> 1 | L28: =IF(OR(WEEKDAY(L$9,1)=3,WEEKDAY(L$9,1)=6),1,0) -> 0 | M28: =IF(OR(WEEKDAY(M$9,1)=3,WEEKDAY(M$9,1)=6),1,0) -> 0 | N28: =IF(OR(WEEKDAY(N$9,1)=3,WEEKDAY(N$9,1)=6),1,0) -> 1 | ... AI28: =IF(OR(WEEKDAY(AI$9,1)=3,WEEKDAY(AI$9,1)=6),1,0) -> 1
B29: 20 | C29: =INDEX('Vias Var Man'!$D$12:$D$3949,MATCH('MAPA VARRIÇÃO MANUAL'!B29,'Vias Var Man'!$B$12:$B$3949)) -> 2 vezes na semana | D29: =VLOOKUP(B29,'Vias Var Man'!$B$12:$H$3949,7,FALSE) -> 6.36122 | E29: =F29*D29 -> 57.25098 | F29: =SUM(G29:AK29) -> 9 | G29: =IF(OR(WEEKDAY(G$9,1)=3,WEEKDAY(G$9,1)=6),1,0) -> 1 | H29: =IF(OR(WEEKDAY(H$9,1)=3,WEEKDAY(H$9,1)=6),1,0) -> 0 | I29: =IF(OR(WEEKDAY(I$9,1)=3,WEEKDAY(I$9,1)=6),1,0) -> 0 | J29: =IF(OR(WEEKDAY(J$9,1)=3,WEEKDAY(J$9,1)=6),1,0) -> 0 | K29: =IF(OR(WEEKDAY(K$9,1)=3,WEEKDAY(K$9,1)=6),1,0) -> 1 | L29: =IF(OR(WEEKDAY(L$9,1)=3,WEEKDAY(L$9,1)=6),1,0) -> 0 | M29: =IF(OR(WEEKDAY(M$9,1)=3,WEEKDAY(M$9,1)=6),1,0) -> 0 | N29: =IF(OR(WEEKDAY(N$9,1)=3,WEEKDAY(N$9,1)=6),1,0) -> 1 | ... AI29: =IF(OR(WEEKDAY(AI$9,1)=3,WEEKDAY(AI$9,1)=6),1,0) -> 1 | AL29: =IF(OR(AL$8=2,AL$8=4,AL$8=6),1,0) -> 0
B30: 21 | C30: =INDEX('Vias Var Man'!$D$12:$D$3949,MATCH('MAPA VARRIÇÃO MANUAL'!B30,'Vias Var Man'!$B$12:$B$3949)) -> 1 vez cada 15 dias | D30: =VLOOKUP(B30,'Vias Var Man'!$B$12:$H$3949,7,FALSE) -> 6.08632 | E30: =F30*D30 -> 0 | F30: =SUM(G30:AK30) -> 0 | AM30: =WEEKNUM(G9) -> 39
B31: 22 | C31: =INDEX('Vias Var Man'!$D$12:$D$3949,MATCH('MAPA VARRIÇÃO MANUAL'!B31,'Vias Var Man'!$B$12:$B$3949)) -> 1 vez cada 15 dias | D31: =VLOOKUP(B31,'Vias Var Man'!$B$12:$H$3949,7,FALSE) -> 5.87822 | E31: =F31*D31 -> 0 | F31: =SUM(G31:AK31) -> 0 | AL31: =IF(OR(AL$8=2,AL$8=4,AL$8=6),1,0) -> 0 | AM31: =WEEKNUM(S10) -> 0
B32: 23 | C32: =INDEX('Vias Var Man'!$D$12:$D$3949,MATCH('MAPA VARRIÇÃO MANUAL'!B32,'Vias Var Man'!$B$12:$B$3949)) -> 1 vez cada 15 dias | D32: =VLOOKUP(B32,'Vias Var Man'!$B$12:$H$3949,7,FALSE) -> 6.06118 | E32: =F32*D32 -> 0 | F32: =SUM(G32:AK32) -> 0
B33: 24 | C33: =INDEX('Vias Var Man'!$D$12:$D$3949,MATCH('MAPA VARRIÇÃO MANUAL'!B33,'Vias Var Man'!$B$12:$B$3949)) -> 1 vez cada 15 dias | D33: =VLOOKUP(B33,'Vias Var Man'!$B$12:$H$3949,7,FALSE) -> 6.21326 | E33: =F33*D33 -> 0 | F33: =SUM(G33:AK33) -> 0 | AL33: =IF(OR(AL$8=2,AL$8=4,AL$8=6),1,0) -> 0
B34: 25 | C34: =INDEX('Vias Var Man'!$D$12:$D$3949,MATCH('MAPA VARRIÇÃO MANUAL'!B34,'Vias Var Man'!$B$12:$B$3949)) -> 1 vez cada 15 dias | D34: =VLOOKUP(B34,'Vias Var Man'!$B$12:$H$3949,7,FALSE) -> 6.05748 | E34: =F34*D34 -> 0 | F34: =SUM(G34:AK34) -> 0
B35: 26 | C35: =INDEX('Vias Var Man'!$D$12:$D$3949,MATCH('MAPA VARRIÇÃO MANUAL'!B35,'Vias Var Man'!$B$12:$B$3949)) -> 1 vez cada 15 dias | D35: =VLOOKUP(B35,'Vias Var Man'!$B$12:$H$3949,7,FALSE) -> 5.9929 | E35: =F35*D35 -> 0 | F35: =SUM(G35:AK35) -> 0 | AL35: =IF(OR(AL$8=2,AL$8=4,AL$8=6),1,0) -> 0
B36: 27 | C36: =INDEX('Vias Var Man'!$D$12:$D$3949,MATCH('MAPA VARRIÇÃO MANUAL'!B36,'Vias Var Man'!$B$12:$B$3949)) -> 1 vez cada 15 dias | D36: =VLOOKUP(B36,'Vias Var Man'!$B$12:$H$3949,7,FALSE) -> 6.0505 | E36: =F36*D36 -> 0 | F36: =SUM(G36:AK36) -> 0
B37: 28 | C37: =INDEX('Vias Var Man'!$D$12:$D$3949,MATCH('MAPA VARRIÇÃO MANUAL'!B37,'Vias Var Man'!$B$12:$B$3949)) -> 1 vez cada 15 dias | D37: =VLOOKUP(B37,'Vias Var Man'!$B$12:$H$3949,7,FALSE) -> 5.83544 | E37: =F37*D37 -> 0 | F37: =SUM(G37:AK37) -> 0 | AL37: =IF(OR(AL$8=2,AL$8=4,AL$8=6),1,0) -> 0
B38: 29 | C38: =INDEX('Vias Var Man'!$D$12:$D$3949,MATCH('MAPA VARRIÇÃO MANUAL'!B38,'Vias Var Man'!$B$12:$B$3949)) -> 1 vez na semana | D38: =VLOOKUP(B38,'Vias Var Man'!$B$12:$H$3949,7,FALSE) -> 6.00716 | E38: =F38*D38 -> 24.02864 | F38: =SUM(G38:AK38) -> 4 | G38: =IF(WEEKDAY(G$9,1)=2,1,0) -> 0 | H38: =IF(WEEKDAY(H$9,1)=2,1,0) -> 0 | I38: =IF(WEEKDAY(I$9,1)=2,1,0) -> 0 | J38: =IF(WEEKDAY(J$9,1)=2,1,0) -> 1 | K38: =IF(WEEKDAY(K$9,1)=2,1,0) -> 0 | L38: =IF(WEEKDAY(L$9,1)=2,1,0) -> 0 | M38: =IF(WEEKDAY(M$9,1)=2,1,0) -> 0 | N38: =IF(WEEKDAY(N$9,1)=2,1,0) -> 0 | ... AI38: =IF(WEEKDAY(AI$9,1)=2,1,0) -> 0
B39: 30 | C39: =INDEX('Vias Var Man'!$D$12:$D$3949,MATCH('MAPA VARRIÇÃO MANUAL'!B39,'Vias Var Man'!$B$12:$B$3949)) -> 1 vez na semana | D39: =VLOOKUP(B39,'Vias Var Man'!$B$12:$H$3949,7,FALSE) -> 6.32934 | E39: =F39*D39 -> 25.31736 | F39: =SUM(G39:AK39) -> 4 | G39: =IF(WEEKDAY(G$9,1)=2,1,0) -> 0 | H39: =IF(WEEKDAY(H$9,1)=2,1,0) -> 0 | I39: =IF(WEEKDAY(I$9,1)=2,1,0) -> 0 | J39: =IF(WEEKDAY(J$9,1)=2,1,0) -> 1 | K39: =IF(WEEKDAY(K$9,1)=2,1,0) -> 0 | L39: =IF(WEEKDAY(L$9,1)=2,1,0) -> 0 | M39: =IF(WEEKDAY(M$9,1)=2,1,0) -> 0 | N39: =IF(WEEKDAY(N$9,1)=2,1,0) -> 0 | ... AI39: =IF(WEEKDAY(AI$9,1)=2,1,0) -> 0 | AL39: =IF(OR(AL$8=2,AL$8=4,AL$8=6),1,0) -> 0
B40: 31 | C40: =INDEX('Vias Var Man'!$D$12:$D$3949,MATCH('MAPA VARRIÇÃO MANUAL'!B40,'Vias Var Man'!$B$12:$B$3949)) -> 1 vez na semana | D40: =VLOOKUP(B40,'Vias Var Man'!$B$12:$H$3949,7,FALSE) -> 6.45094 | E40: =F40*D40 -> 25.80376 | F40: =SUM(G40:AK40) -> 4 | G40: =IF(WEEKDAY(G$9,1)=2,1,0) -> 0 | H40: =IF(WEEKDAY(H$9,1)=2,1,0) -> 0 | I40: =IF(WEEKDAY(I$9,1)=2,1,0) -> 0 | J40: =IF(WEEKDAY(J$9,1)=2,1,0) -> 1 | K40: =IF(WEEKDAY(K$9,1)=2,1,0) -> 0 | L40: =IF(WEEKDAY(L$9,1)=2,1,0) -> 0 | M40: =IF(WEEKDAY(M$9,1)=2,1,0) -> 0 | N40: =IF(WEEKDAY(N$9,1)=2,1,0) -> 0 | ... AI40: =IF(WEEKDAY(AI$9,1)=2,1,0) -> 0
B41: 32 | C41: =INDEX('Vias Var Man'!$D$12:$D$3949,MATCH('MAPA VARRIÇÃO MANUAL'!B41,'Vias Var Man'!$B$12:$B$3949)) -> 1 vez na semana | D41: =VLOOKUP(B41,'Vias Var Man'!$B$12:$H$3949,7,FALSE) -> 6.3094 | E41: =F41*D41 -> 25.2376 | F41: =SUM(G41:AK41) -> 4 | G41: =IF(WEEKDAY(G$9,1)=2,1,0) -> 0 | H41: =IF(WEEKDAY(H$9,1)=2,1,0) -> 0 | I41: =IF(WEEKDAY(I$9,1)=2,1,0) -> 0 | J41: =IF(WEEKDAY(J$9,1)=2,1,0) -> 1 | K41: =IF(WEEKDAY(K$9,1)=2,1,0) -> 0 | L41: =IF(WEEKDAY(L$9,1)=2,1,0) -> 0 | M41: =IF(WEEKDAY(M$9,1)=2,1,0) -> 0 | N41: =IF(WEEKDAY(N$9,1)=2,1,0) -> 0 | ... AI41: =IF(WEEKDAY(AI$9,1)=2,1,0) -> 0 | AL41: =IF(OR(AL$8=2,AL$8=4,AL$8=6),1,0) -> 0
B42: 33 | C42: =INDEX('Vias Var Man'!$D$12:$D$3949,MATCH('MAPA VARRIÇÃO MANUAL'!B42,'Vias Var Man'!$B$12:$B$3949)) -> 1 vez na semana | D42: =VLOOKUP(B42,'Vias Var Man'!$B$12:$H$3949,7,FALSE) -> 6.25424 | E42: =F42*D42 -> 25.01696 | F42: =SUM(G42:AK42) -> 4 | G42: =IF(WEEKDAY(G$9,1)=2,1,0) -> 0 | H42: =IF(WEEKDAY(H$9,1)=2,1,0) -> 0 | I42: =IF(WEEKDAY(I$9,1)=2,1,0) -> 0 | J42: =IF(WEEKDAY(J$9,1)=2,1,0) -> 1 | K42: =IF(WEEKDAY(K$9,1)=2,1,0) -> 0 | L42: =IF(WEEKDAY(L$9,1)=2,1,0) -> 0 | M42: =IF(WEEKDAY(M$9,1)=2,1,0) -> 0 | N42: =IF(WEEKDAY(N$9,1)=2,1,0) -> 0 | ... AI42: =IF(WEEKDAY(AI$9,1)=2,1,0) -> 0
...

Sheet TabelaRoçadaMec
A1: SERVIÇO | B1: DATA | C1: LOCAL | D1: TIPO DE EQUIPAMENTO | E1: UNIDADE | F1: QUANTIDADE | G1: OBSERVAÇÃO
A2: ROÇADA MECANIZADA | B2: 46259 | C2: Distrito Agroindustrial Noberto Teixeira CENTO E TRINTA E SEIS 11 014E | D2: TR23 | E2: m² | F2: 4812.5272
A3: ROÇADA MECANIZADA | B3: 46259 | C3: Distrito Agroindustrial Noberto Teixeira CENTO E TRINTA E SEIS 11 014E | D3: TR23 | E3: m² | F3: 1077.9659
A4: ROÇADA MECANIZADA | B4: 46259 | C4: Distrito Agroindustrial Noberto Teixeira CENTO E TRINTA E SEIS 11 014E | D4: TR23 | E4: m² | F4: 2328.7112
A5: ROÇADA MECANIZADA | B5: 46259 | C5: Distrito Agroindustrial Noberto Teixeira CENTO E TRINTA E SEIS 11 014E | D5: TR23 | E5: m² | F5: 1052.0936
A6: ROÇADA MECANIZADA | B6: 46259 | C6: Distrito Agroindustrial Noberto Teixeira CENTO E TRINTA E SEIS 11 014E | D6: TR-31 | E6: m² | F6: 6339.4
A7: ROÇADA MECANIZADA | B7: 46259 | C7: Distrito Agroindustrial Noberto Teixeira CENTO E TRINTA E SEIS 11 014E | D7: TR04 | E7: m² | F7: 4593.7119
A8: ROÇADA MECANIZADA | B8: 46259 | C8: Distrito Agroindustrial Noberto Teixeira CENTO E TRINTA E SEIS 11 014E | D8: TR04 | E8: m² | F8: 1477.7642
A9: ROÇADA MECANIZADA | B9: 46259 | C9: Distrito Agroindustrial Noberto Teixeira CENTO E TRINTA E SEIS 11 014E | D9: TR19 | E9: m² | F9: 5647.3058
A10: ROÇADA MECANIZADA | B10: 46259 | C10: Buriti Sereno CENTO E TRINTA E SEIS 234 6 | D10: TR03 | E10: m² | F10: 498.33974
A11: ROÇADA MECANIZADA | B11: 46259 | C11: Buriti Sereno CENTO E TRINTA E SEIS 234 9 | D11: TR03 | E11: m² | F11: 499.18049
A12: ROÇADA MECANIZADA | B12: 46259 | C12: Buriti Sereno CENTO E TRINTA E SEIS 234 10 | D12: TR03 | E12: m² | F12: 499.18365
A13: ROÇADA MECANIZADA | B13: 46259 | C13: Buriti Sereno CENTO E TRINTA E SEIS 234 11 | D13: TR03 | E13: m² | F13: 499.18245
... A1424: ROÇADA MECANIZADA | B1424: 46268 | C1424: Rosa dos Ventos CENTO E TRINTA E SEIS 122 11 | D1424: TR12 | E1424: m² | F1424: 446.78804
A1425: ROÇADA MECANIZADA | B1425: 46268 | D1425: TR12 | E1425: m² | F1425: 10697.692
A1426: ROÇADA MECANIZADA | B1426: 46268 | C1426: Itamaraty CENTO E TRINTA E SEIS 5 11 | D1426: TR12 | E1426: m² | F1426: 459.15991
A1427: ROÇADA MECANIZADA | B1427: 46268 | C1427: Rosa dos Ventos CENTO E TRINTA E SEIS 123 31 | D1427: TR15 | E1427: m² | F1427: 458.94535
A1428: ROÇADA MECANIZADA | B1428: 46268 | C1428: Rosa dos Ventos CENTO E TRINTA E SEIS 130 18 | D1428: TR15 | E1428: m² | F1428: 620.50814
A1429: ROÇADA MECANIZADA | B1429: 46268 | C1429: Rosa dos Ventos CENTO E TRINTA E SEIS 130 16 | D1429: TR15 | E1429: m² | F1429: 474.6617
A1430: ROÇADA MECANIZADA | B1430: 46268 | C1430: Rosa dos Ventos CENTO E TRINTA E SEIS 130 17 | D1430: TR15 | E1430: m² | F1430: 811.69129
A1431: ROÇADA MECANIZADA | B1431: 46268 | C1431: Rosa dos Ventos CENTO E TRINTA E SEIS 130 9 | D1431: TR15 | E1431: m² | F1431: 487.22409
A1432: ROÇADA MECANIZADA | B1432: 46268 | C1432: Rosa dos Ventos CENTO E TRINTA E SEIS 130 20 | D1432: TR15 | E1432: m² | F1432: 423.05379
A1433: ROÇADA MECANIZADA | B1433: 46268 | C1433: Rosa dos Ventos CENTO E TRINTA E SEIS 130 15 | D1433: TR15 | E1433: m² | F1433: 450.49697
A1434: ROÇADA MECANIZADA | B1434: 46268 | C1434: Rosa dos Ventos CENTO E TRINTA E SEIS 117 1 | D1434: TR15 | E1434: m² | F1434: 974.65349
A1435: ROÇADA MECANIZADA | B1435: 46268 | C1435: Rosa dos Ventos CENTO E TRINTA E SEIS 117 9 | D1435: TR15 | E1435: m² | F1435: 574.94374
A1436: ROÇADA MECANIZADA | B1436: 46268 | C1436: Rosa dos Ventos CENTO E TRINTA E SEIS 117 8 | D1436: TR15 | E1436: m² | F1436: 552.32289
A1437: ROÇADA MECANIZADA | B1437: 46268 | C1437: Rosa dos Ventos CENTO E TRINTA E SEIS 117 7 | D1437: TR15 | E1437: m² | F1437: 1014.4546
... A2029: ROÇADA MECANIZADA | B2029: 46273 | C2029: Solar Garden II CENTO E TRINTA E SEIS APM 1 | D2029: TR07 | E2029: m² | F2029: 2058.782
A2030: ROÇADA MECANIZADA | B2030: 46274 | D2030: TR14 | E2030: m² | F2030: 853.51783
A2031: ROÇADA MECANIZADA | B2031: 46274 | D2031: TR14 | E2031: m² | F2031: 971.1308
A2032: ROÇADA MECANIZADA | B2032: 46274 | D2032: TR14 | E2032: m² | F2032: 74.210389
A2033: ROÇADA MECANIZADA | B2033: 46274 | D2033: TR14 | E2033: m² | F2033: 103.05646
A2034: ROÇADA MECANIZADA | B2034: 46274 | D2034: TR14 | E2034: m² | F2034: 323.85799
A2035: ROÇADA MECANIZADA | B2035: 46274 | C2035: Independência 3 Complemento CENTO E TRINTA E SEIS 8A 001A | D2035: TR14 | E2035: m² | F2035: 554.8684
A2036: ROÇADA MECANIZADA | B2036: 46274 | C2036: Oliveira CENTO E TRINTA E SEIS 8 15 | D2036: TR14 | E2036: m² | F2036: 473.72142
A2037: ROÇADA MECANIZADA | B2037: 46274 | C2037: Oliveira CENTO E TRINTA E SEIS 12B 18 | D2037: TR14 | E2037: m² | F2037: 661.35172
A2038: ROÇADA MECANIZADA | B2038: 46274 | C2038: Oliveira CENTO E TRINTA E SEIS 12B 16 | D2038: TR14 | E2038: m² | F2038: 391.60673
A2039: ROÇADA MECANIZADA | B2039: 46274 | C2039: Oliveira CENTO E TRINTA E SEIS 12B 15 | D2039: TR14 | E2039: m² | F2039: 398.80775
A2040: ROÇADA MECANIZADA | B2040: 46274 | C2040: Oliveira CENTO E TRINTA E SEIS 12B 14 | D2040: TR14 | E2040: m² | F2040: 400.93618
A2041: ROÇADA MECANIZADA | B2041: 46274 | C2041: Oliveira CENTO E TRINTA E SEIS 12B 12 | D2041: TR14 | E2041: m² | F2041: 396.05396
...

Sheet ROÇADA MECANIZADA
C2: OBJETO: Contratação de empresa especializada para a prestação de “Serviços de limpeza pública urbana do município de Aparecida de Goiânia, Estado de Goiás, compreendendo os serviços de coleta domiciliar e comercial, varrição mecanizada, varrição manual, e equipe de serviços diversos de remoção de entulhos e materiais inservíveis, capina e raspagem”
C3: CONCORRÊNCIA PÚBLICA TIPO: | D3: MENOR PREÇO N° 012/2023
C4: CONTRATO: | D4: =#REF! -> #REF!
C5: DATA: | D5: =#REF! -> #REF!
C6: CONTRATADA: CONSORCIO SQ APARECIDA SUSTENTÁVEL - CNPJ.: 56.309.119/0001-03
C7: PERÍODO: | D7: =#REF! -> #REF!
B9: =#REF! -> #REF!
B11: EXECUÇÃO
B12: Dia | C12: Setor | D12: Rua | E12: Equipamento | F12: Área | G12: Quadra | H12: Lote | I12: Nº Inscrição Imobiliária
B13: 46290 | C13: Primavera | D13: CENTO E TRINTA E SEIS | E13: TR13 | F13: 934.81973 | G13: 41 | H13: 18 | I13: 68520 | K13: =SUM(F13:F1048576) -> 2659324.8
B14: 46290 | C14: Primavera | D14: CENTO E TRINTA E SEIS | E14: TR13 | F14: 532.32615 | G14: 41 | H14: 21 | I14: 68523
B15: 46290 | C15: Primavera | D15: CENTO E TRINTA E SEIS | E15: TR13 | F15: 532.70286 | G15: 41 | H15: 20 | I15: 68522
B16: 46290 | C16: Primavera | D16: CENTO E TRINTA E SEIS | E16: TR13 | F16: 538.36459 | G16: 41 | H16: 17 | I16: 68519
B17: 46290 | C17: Primavera | D17: CENTO E TRINTA E SEIS | E17: TR13 | F17: 582.58787 | G17: 41 | H17: 16 | I17: 68518
B18: 46290 | C18: Primavera | D18: CENTO E TRINTA E SEIS | E18: TR13 | F18: 556.30073 | G18: 41 | H18: 12 | I18: 68514
B19: 46290 | C19: Primavera | D19: CENTO E TRINTA E SEIS | E19: TR13 | F19: 562.30229 | G19: 41 | H19: 14 | I19: 68516
B20: 46290 | C20: Primavera | D20: CENTO E TRINTA E SEIS | E20: TR13 | F20: 728.37467 | G20: 41 | H20: 15 | I20: 68517
B21: 46290 | C21: Primavera | D21: CENTO E TRINTA E SEIS | E21: TR13 | F21: 561.93671 | G21: 41 | H21: 13 | I21: 68515
B22: 46290 | C22: Primavera | D22: CENTO E TRINTA E SEIS | E22: TR13 | F22: 489.973 | G22: 41 | H22: 4 | I22: 68506
B23: 46290 | C23: Primavera | D23: CENTO E TRINTA E SEIS | E23: TR13 | F23: 477.47608 | G23: 41 | H23: 5 | I23: 68507
B24: 46290 | C24: Primavera | D24: CENTO E TRINTA E SEIS | E24: TR13 | F24: 532.70518 | G24: 41 | H24: 26 | I24: 68528
B25: 46290 | C25: Primavera | D25: CENTO E TRINTA E SEIS | E25: TR13 | F25: 532.32595 | G25: 41 | H25: 25 | I25: 68527
... B225: 46290 | C225: Primavera | D225: CENTO E TRINTA E SEIS | E225: TR04 | F225: 582.30574 | G225: 12 | H225: 10 | I225: 66847
B226: 46290 | C226: Primavera | D226: CENTO E TRINTA E SEIS | E226: TR04 | F226: 714.61139 | I226: 0
B227: 46290 | C227: Eldorado | D227: CENTO E TRINTA E SEIS | E227: TR07 | F227: 490.43141 | G227: 43 | H227: 21 | I227: 222560
B228: 46290 | C228: Eldorado | D228: CENTO E TRINTA E SEIS | E228: TR07 | F228: 473.44528 | G228: 43 | H228: 20 | I228: 222559
B229: 46290 | C229: Eldorado | D229: CENTO E TRINTA E SEIS | E229: TR07 | F229: 1135.9925 | G229: 43 | H229: 19 | I229: 222558
B230: 46290 | C230: Eldorado | D230: CENTO E TRINTA E SEIS | E230: TR07 | F230: 510.45306 | G230: 42 | H230: 21 | I230: 222351
B231: 46290 | C231: Eldorado | D231: CENTO E TRINTA E SEIS | E231: TR07 | F231: 569.99039 | G231: 42 | H231: 22 | I231: 222352
B232: 46290 | C232: Eldorado | D232: CENTO E TRINTA E SEIS | E232: TR07 | F232: 413.67116 | G232: 42 | H232: 24 | I232: 222354
B233: 46290 | C233: Eldorado | D233: CENTO E TRINTA E SEIS | E233: TR07 | F233: 457.06349 | G233: 42 | H233: 25 | I233: 222355
B234: 46290 | C234: Eldorado | D234: CENTO E TRINTA E SEIS | E234: TR07 | F234: 557.21111 | G234: 42 | H234: 28 | I234: 222358
B235: 46290 | C235: Eldorado | D235: CENTO E TRINTA E SEIS | E235: TR07 | F235: 662.12197 | G235: 42 | H235: 27 | I235: 222357
B236: 46290 | C236: Eldorado | D236: CENTO E TRINTA E SEIS | E236: TR07 | F236: 1374.7382 | G236: 42 | H236: 26 | I236: 222356
B237: 46290 | C237: Eldorado | D237: CENTO E TRINTA E SEIS | E237: TR07 | F237: 514.10423 | G237: 43 | H237: 22 | I237: 222561
B238: 46290 | C238: Eldorado | D238: CENTO E TRINTA E SEIS | E238: TR07 | F238: 391.0874 | G238: 33 | H238: 13 | I238: 222679
... B307: 46293 | C307: Helvecia | D307: CENTO E TRINTA E SEIS | E307: TR09 | F307: 770.53057 | G307: 36 | H307: 15 | I307: 36023
B308: 46293 | C308: Helvecia | D308: CENTO E TRINTA E SEIS | E308: TR09 | F308: 1442.0405 | G308: AV | I308: 0
B309: 46293 | C309: Helvecia | D309: CENTO E TRINTA E SEIS | E309: TR09 | F309: 1798.4466 | G309: AV | I309: 0
B310: 46293 | C310: Helvecia | D310: CENTO E TRINTA E SEIS | E310: TR09 | F310: 420.97064 | G310: 22 | H310: 4 | I310: 4626
...

Sheet TabelaRoçadaManual
A1: SERVIÇO | B1: DATA | C1: LOCAL | D1: TIPO DE EQUIPAMENTO | E1: UNIDADE | F1: QUANTIDADE | G1: OBSERVAÇÃO
A2: ROÇADA MANUAL | B2: 46259 | C2: Bela Vista Continuacao CENTO E TRINTA E SEIS | E2: m² | F2: 8132.1496
A3: ROÇADA MANUAL | B3: 46259 | C3: Cidade Satelite Sao Luiz CENTO E TRINTA E SEIS | E3: m² | F3: 1371.4003
A4: ROÇADA MANUAL | B4: 46259 | C4: Cidade Vera Cruz CENTO E TRINTA E SEIS | E4: m² | F4: 9930.4565
A5: ROÇADA MANUAL | B5: 46259 | C5: Mont Serrat CENTO E TRINTA E SEIS | E5: m² | F5: 157.43244
A6: ROÇADA MANUAL | B6: 46259 | C6: Mont Serrat CENTO E TRINTA E SEIS | E6: m² | F6: 789.91066
A7: ROÇADA MANUAL | B7: 46259 | C7: Garavelo CENTO E TRINTA E SEIS | E7: m² | F7: 17415.845
A8: ROÇADA MANUAL | B8: 46259 | C8: Helvecia CENTO E TRINTA E SEIS | E8: m² | F8: 1504.7659
A9: ROÇADA MANUAL | B9: 46259 | C9: Cidade Satelite Sao Luiz CENTO E TRINTA E SEIS | E9: m² | F9: 1035.2988
A10: ROÇADA MANUAL | B10: 46259 | C10: Cidade Satelite Sao Luiz CENTO E TRINTA E SEIS | E10: m² | F10: 1712.805
A11: ROÇADA MANUAL | B11: 46259 | C11: Garavelo CENTO E TRINTA E SEIS | E11: m² | F11: 403.14738
A12: ROÇADA MANUAL | B12: 46259 | C12: Garavelo CENTO E TRINTA E SEIS | E12: m² | F12: 16175.737
A13: ROÇADA MANUAL | B13: 46259 | C13: Nova Era CENTO E TRINTA E SEIS | E13: m² | F13: 381.10346
... A55: ROÇADA MANUAL | B55: 46260 | C55: Sitios Santa Luzia CENTO E TRINTA E SEIS | E55: m² | F55: 162.57187
A56: ROÇADA MANUAL | B56: 46260 | C56: Sitios Santa Luzia CENTO E TRINTA E SEIS | D56: TR29 | E56: m² | F56: 230.342
A57: ROÇADA MANUAL | B57: 46260 | C57: Sitios Santa Luzia CENTO E TRINTA E SEIS | D57: TR29 | E57: m² | F57: 7001.2647
A58: ROÇADA MANUAL | B58: 46260 | C58: Alzira CENTO E TRINTA E SEIS | E58: m² | F58: 481.68701
A59: ROÇADA MANUAL | B59: 46260 | C59: Alzira CENTO E TRINTA E SEIS | E59: m² | F59: 291.97383
A60: ROÇADA MANUAL | B60: 46260 | C60: Ibirapuera CENTO E TRINTA E SEIS | E60: m² | F60: 153.52647
A61: ROÇADA MANUAL | B61: 46260 | C61: Tiradentes CENTO E TRINTA E SEIS | E61: m² | F61: 216.92922
